Workbook
Name LocalisationRemorque: 'DB remorque'!$A$1:$O$299
Name PlanningMois: Tableau!$E$2:$AZ$190

Sheet Tableau
B1: 2027 | C1: Emplacement | D1: Axe (out ► in) | E1: Janvier | F1: IN | G1: Janvier | H1: OUT | I1: Février | J1: IN | K1: Février | L1: OUT | M1: Mars | N1: IN | O1: Mars | P1: OUT | Q1: Avril | R1: IN | S1: Avril | T1: OUT | U1: Mai | V1: IN | W1: Mai | X1: OUT | Y1: Juin | Z1: IN | AA1: Juin | AB1: OUT | AC1: Juillet | AD1: IN | AE1: Juillet | AF1: OUT | AG1: Août | AH1: IN | AI1: Août | AJ1: OUT | AK1: Septembre | AL1: IN | AM1: Septembre | AN1: OUT | AO1: Octobre | AP1: IN | AQ1: Octobre | AR1: OUT | AS1: Novembre | AT1: IN | AU1: Novembre | AV1: OUT | AW1: Décembre | AX1: IN | AY1: Décembre | AZ1: OUT | BA1: Plopsa | BB1: Stock | BC1: Carbelle
B2: =VLOOKUP($A2,LocalisationRemorque,2,0) -> Remorque non listée | C2: =VLOOKUP($A2,LocalisationRemorque,3,0) | D2: =CONCATENATE(VLOOKUP($A2,LocalisationRemorque,6,0)," ► ",VLOOKUP($A2,LocalisationRemorque,5,0)) -> ►
A3: 102 | B3: =VLOOKUP($A3,LocalisationRemorque,2,0) -> Nivelles | C3: =VLOOKUP($A3,LocalisationRemorque,3,0) -> Sud Thines | D3: =CONCATENATE(VLOOKUP($A3,LocalisationRemorque,6,0)," ► ",VLOOKUP($A3,LocalisationRemorque,5,0)) -> Nivelles ► Namur | E3: DEMA | F3: OPTION | G3: Usico | H3: Decorex | J3: Cond Salon | S3: DEMA | W3: DEMA | AC3: DEMA | AE3: Decorex | AK3: DEMA | AO3: DEMA | AW3: DEMA
B4: =VLOOKUP($A4,LocalisationRemorque,2,0) -> Remorque non listée | C4: =VLOOKUP($A4,LocalisationRemorque,3,0) | D4: =CONCATENATE(VLOOKUP($A4,LocalisationRemorque,6,0)," ► ",VLOOKUP($A4,LocalisationRemorque,5,0)) -> ►
A5: 104 | B5: =VLOOKUP($A5,LocalisationRemorque,2,0) -> Ottignies | C5: =VLOOKUP($A5,LocalisationRemorque,3,0) -> Clinique | D5: =CONCATENATE(VLOOKUP($A5,LocalisationRemorque,6,0)," ► ",VLOOKUP($A5,LocalisationRemorque,5,0)) -> Rixensart ► Court-Saint-Etienne | E5: JDW | F5: opt | G5: Schmidt cuisines- Wavre | J5: Cond Salon | M5: Schmidt cuisines- Wavre | Y5: Schmidt cuisines- Wavre | AK5: Schmidt cuisines- Wavre | AS5: Schmidt cuisines- Wavre
A6: 105 | B6: =VLOOKUP($A6,LocalisationRemorque,2,0) -> Louvain-la-Neuve | C6: =VLOOKUP($A6,LocalisationRemorque,3,0) -> Corbais | D6: =CONCATENATE(VLOOKUP($A6,LocalisationRemorque,6,0)," ► ",VLOOKUP($A6,LocalisationRemorque,5,0)) -> LLN ► Gembloux | E6: JDW | F6: opt | J6: Cond Salon | AC6: DEMA | AW6: DEMA
A7: 106 | B7: =VLOOKUP($A7,LocalisationRemorque,2,0) -> Wavre | C7: =VLOOKUP($A7,LocalisationRemorque,3,0) -> Grez-Doiceau 1 | D7: =CONCATENATE(VLOOKUP($A7,LocalisationRemorque,6,0)," ► ",VLOOKUP($A7,LocalisationRemorque,5,0)) -> Wavre ► Grez | E7: Schmidt cuisines- Wavre | G7: JDW | H7: opt | M7: Schmidt cuisines- Wavre | Y7: Schmidt cuisines- Wavre | AK7: Schmidt cuisines- Wavre | AS7: Schmidt cuisines- Wavre
A8: 107 | B8: =VLOOKUP($A8,LocalisationRemorque,2,0) -> Wavre | C8: =VLOOKUP($A8,LocalisationRemorque,3,0) -> Grez-Doiceau 2 | D8: =CONCATENATE(VLOOKUP($A8,LocalisationRemorque,6,0)," ► ",VLOOKUP($A8,LocalisationRemorque,5,0)) -> LLN ► Wavre | E8: Schmidt cuisines- Wavre | J8: Cond Salon | M8: Schmidt cuisines- Wavre | Y8: Schmidt cuisines- Wavre | AK8: Schmidt cuisines- Wavre | AS8: Schmidt cuisines- Wavre
A9: 108 | B9: =VLOOKUP($A9,LocalisationRemorque,2,0) -> Wavre | C9: =VLOOKUP($A9,LocalisationRemorque,3,0) -> Grez-Doiceau 3 | D9: =CONCATENATE(VLOOKUP($A9,LocalisationRemorque,6,0)," ► ",VLOOKUP($A9,LocalisationRemorque,5,0)) -> Wavre ► Grez | E9: Schmidt cuisines- Wavre | M9: Schmidt cuisines- Wavre | Y9: Schmidt cuisines- Wavre | AC9: Schmidt cuisines- Wavre | AK9: Schmidt cuisines- Wavre | AS9: Schmidt cuisines- Wavre
A10: 109 | B10: =VLOOKUP($A10,LocalisationRemorque,2,0) -> Jodoigne | C10: =VLOOKUP($A10,LocalisationRemorque,3,0) -> Mélin | D10: =CONCATENATE(VLOOKUP($A10,LocalisationRemorque,6,0)," ► ",VLOOKUP($A10,LocalisationRemorque,5,0)) -> Jodoigne ► Beauvechain | J10: Cond Salon
A11: 110 | B11: =VLOOKUP($A11,LocalisationRemorque,2,0) -> Jodoigne | C11: =VLOOKUP($A11,LocalisationRemorque,3,0) -> Entree Jodoigne | D11: =CONCATENATE(VLOOKUP($A11,LocalisationRemorque,6,0)," ► ",VLOOKUP($A11,LocalisationRemorque,5,0)) -> Jodoigne ► Tirlemont
A12: 111 | B12: =VLOOKUP($A12,LocalisationRemorque,2,0) -> Beauvechain | C12: =VLOOKUP($A12,LocalisationRemorque,3,0) -> Nodebais | D12: =CONCATENATE(VLOOKUP($A12,LocalisationRemorque,6,0)," ► ",VLOOKUP($A12,LocalisationRemorque,5,0)) -> Éghezée ► Hamme | E12: Schmidt cuisines- Wavre | M12: Schmidt cuisines- Wavre | Y12: Schmidt cuisines- Wavre | AC12: Schmidt cuisines- Wavre | AK12: Schmidt cuisines- Wavre | AS12: Schmidt cuisines- Wavre
A13: 112 | B13: =VLOOKUP($A13,LocalisationRemorque,2,0) -> Incourt | C13: =VLOOKUP($A13,LocalisationRemorque,3,0) -> Incourt | D13: =CONCATENATE(VLOOKUP($A13,LocalisationRemorque,6,0)," ► ",VLOOKUP($A13,LocalisationRemorque,5,0)) -> Louvain ► Éghezée
A14: 113 | B14: =VLOOKUP($A14,LocalisationRemorque,2,0) -> Perwez | C14: =VLOOKUP($A14,LocalisationRemorque,3,0) -> Perwez | D14: =CONCATENATE(VLOOKUP($A14,LocalisationRemorque,6,0)," ► ",VLOOKUP($A14,LocalisationRemorque,5,0)) -> Jodoigne ► E411 | J14: Cond Salon
A15: 114 | B15: =VLOOKUP($A15,LocalisationRemorque,2,0) -> Perwez | C15: =VLOOKUP($A15,LocalisationRemorque,3,0) -> Sortie E411 | D15: =CONCATENATE(VLOOKUP($A15,LocalisationRemorque,6,0)," ► ",VLOOKUP($A15,LocalisationRemorque,5,0)) -> E411 ► Jodoigne | E15: JDW | F15: opt
A26: 201 | B26: =VLOOKUP($A26,LocalisationRemorque,2,0) -> Hannut | C26: =VLOOKUP($A26,LocalisationRemorque,3,0) -> Hannut-Saint Trond | D26: =CONCATENATE(VLOOKUP($A26,LocalisationRemorque,6,0)," ► ",VLOOKUP($A26,LocalisationRemorque,5,0)) -> Hannut ► Saint-Trond
A27: 202 | B27: =VLOOKUP($A27,LocalisationRemorque,2,0) -> Hannut | C27: =VLOOKUP($A27,LocalisationRemorque,3,0) -> Braives | D27: =CONCATENATE(VLOOKUP($A27,LocalisationRemorque,6,0)," ► ",VLOOKUP($A27,LocalisationRemorque,5,0)) -> Hannut ► E42
A28: 203 | B28: =VLOOKUP($A28,LocalisationRemorque,2,0) -> Huy | C28: =VLOOKUP($A28,LocalisationRemorque,3,0) -> Wanze | D28: =CONCATENATE(VLOOKUP($A28,LocalisationRemorque,6,0)," ► ",VLOOKUP($A28,LocalisationRemorque,5,0)) -> Éghezée ► E42 | E28: Carbelle | I28: Carbelle | M28: Carbelle | Q28: Carbelle | U28: Carbelle | BA28: Plopsa | BC28: C
A29: 204 | B29: =VLOOKUP($A29,LocalisationRemorque,2,0) -> Huy | C29: =VLOOKUP($A29,LocalisationRemorque,3,0) -> Vinalmont | D29: =CONCATENATE(VLOOKUP($A29,LocalisationRemorque,6,0)," ► ",VLOOKUP($A29,LocalisationRemorque,5,0)) -> Huy ► E42 | E29: Carbelle | I29: Carbelle | M29: Carbelle | Q29: Carbelle | U29: Carbelle | BA29: Plopsa | BC29: C
A30: 205 | B30: =VLOOKUP($A30,LocalisationRemorque,2,0) -> Huy | C30: =VLOOKUP($A30,LocalisationRemorque,3,0) -> Villers-Le-Bouillet | D30: =CONCATENATE(VLOOKUP($A30,LocalisationRemorque,6,0)," ► ",VLOOKUP($A30,LocalisationRemorque,5,0)) -> Huy ► E42 | E30: Carbelle | I30: Carbelle | M30: Carbelle | Q30: Carbelle | U30: Carbelle | BA30: Plopsa | BC30: C
A31: 206 | B31: =VLOOKUP($A31,LocalisationRemorque,2,0) -> Huy | C31: =VLOOKUP($A31,LocalisationRemorque,3,0) -> Ombret | D31: =CONCATENATE(VLOOKUP($A31,LocalisationRemorque,6,0)," ► ",VLOOKUP($A31,LocalisationRemorque,5,0)) -> Seraing ► Huy | E31: Carbelle | I31: Carbelle | M31: Carbelle | Q31: Carbelle | U31: Carbelle | BA31: Plopsa | BC31: C
A32: 207 | B32: =VLOOKUP($A32,LocalisationRemorque,2,0) -> Huy | C32: =VLOOKUP($A32,LocalisationRemorque,3,0) -> Solière | D32: =CONCATENATE(VLOOKUP($A32,LocalisationRemorque,6,0)," ► ",VLOOKUP($A32,LocalisationRemorque,5,0)) -> Ohey ► Huy | E32: Carbelle | I32: Carbelle | M32: Carbelle | Q32: Carbelle | U32: Carbelle | BA32: Plopsa | BC32: C
A33: 208 | B33: =VLOOKUP($A33,LocalisationRemorque,2,0) -> Huy | C33: =VLOOKUP($A33,LocalisationRemorque,3,0) -> Tihange | D33: =CONCATENATE(VLOOKUP($A33,LocalisationRemorque,6,0)," ► ",VLOOKUP($A33,LocalisationRemorque,5,0)) -> Hamoir ► Huy | E33: Carbelle | I33: Carbelle | M33: Carbelle | Q33: Carbelle | U33: Carbelle | BA33: Plopsa | BC33: C
A34: 209 | B34: =VLOOKUP($A34,LocalisationRemorque,2,0) -> Huy | C34: =VLOOKUP($A34,LocalisationRemorque,3,0) -> Pont de bonne | D34: =CONCATENATE(VLOOKUP($A34,LocalisationRemorque,6,0)," ► ",VLOOKUP($A34,LocalisationRemorque,5,0)) -> Havelange ► Huy | E34: Carbelle | I34: Carbelle | M34: Carbelle | Q34: Carbelle | U34: Carbelle | BA34: Plopsa | BC34: C
A35: 210 | B35: =VLOOKUP($A35,LocalisationRemorque,2,0) -> Huy | C35: =VLOOKUP($A35,LocalisationRemorque,3,0) -> Nandrin | D35: =CONCATENATE(VLOOKUP($A35,LocalisationRemorque,6,0)," ► ",VLOOKUP($A35,LocalisationRemorque,5,0)) -> Marche-en-Famenne ► Liege | E35: Carbelle | I35: Carbelle | M35: Carbelle | Q35: Carbelle | U35: Carbelle | AC35: Grottes de Han | AG35: Grottes de Han | AO35: Grottes de Han | BA35: Plopsa | BC35: C
A36: 211 | B36: =VLOOKUP($A36,LocalisationRemorque,2,0) -> Huy | C36: =VLOOKUP($A36,LocalisationRemorque,3,0) -> Soheit-Tinlot | D36: =CONCATENATE(VLOOKUP($A36,LocalisationRemorque,6,0)," ► ",VLOOKUP($A36,LocalisationRemorque,5,0)) -> Marche-en-Famenne ► Liege | E36: Carbelle | I36: Carbelle | M36: Carbelle | Q36: Carbelle | U36: Carbelle | BA36: Plopsa | BC36: C
A37: 212 | B37: =VLOOKUP($A37,LocalisationRemorque,2,0) -> Flemalle | C37: =VLOOKUP($A37,LocalisationRemorque,3,0) -> Pont dYvoz-Ramet | D37: =CONCATENATE(VLOOKUP($A37,LocalisationRemorque,6,0)," ► ",VLOOKUP($A37,LocalisationRemorque,5,0)) -> Liège ► Huy
A38: 213 | B38: =VLOOKUP($A38,LocalisationRemorque,2,0) -> Fexhe-le-Haut-Clocher | C38: =VLOOKUP($A38,LocalisationRemorque,3,0) -> Simonis | D38: =CONCATENATE(VLOOKUP($A38,LocalisationRemorque,6,0)," ► ",VLOOKUP($A38,LocalisationRemorque,5,0)) -> Waremme ► Bierset
A39: 214 | B39: =VLOOKUP($A39,LocalisationRemorque,2,0) -> Fexhe-le-Haut-Clocher | C39: =VLOOKUP($A39,LocalisationRemorque,3,0) -> Château d'eau Jeneffe | D39: =CONCATENATE(VLOOKUP($A39,LocalisationRemorque,6,0)," ► ",VLOOKUP($A39,LocalisationRemorque,5,0)) -> Tongres ► Amay
A40: 215 | B40: =VLOOKUP($A40,LocalisationRemorque,2,0) -> Fexhe-le-Haut-Clocher | C40: =VLOOKUP($A40,LocalisationRemorque,3,0) -> Noville | D40: =CONCATENATE(VLOOKUP($A40,LocalisationRemorque,6,0)," ► ",VLOOKUP($A40,LocalisationRemorque,5,0)) -> Amay ► E40
A41: 216 | B41: =VLOOKUP($A41,LocalisationRemorque,2,0) -> Waremme | C41: =VLOOKUP($A41,LocalisationRemorque,3,0) -> Waremme 1 | D41: =CONCATENATE(VLOOKUP($A41,LocalisationRemorque,6,0)," ► ",VLOOKUP($A41,LocalisationRemorque,5,0)) -> Huy ► Waremme
A42: 227 | B42: =VLOOKUP($A42,LocalisationRemorque,2,0) -> Waremme | C42: =VLOOKUP($A42,LocalisationRemorque,3,0) -> Waremme 2 | D42: =CONCATENATE(VLOOKUP($A42,LocalisationRemorque,6,0)," ► ",VLOOKUP($A42,LocalisationRemorque,5,0)) -> Huy ► Waremme
A43: 217 | B43: =VLOOKUP($A43,LocalisationRemorque,2,0) -> Viemme | C43: =VLOOKUP($A43,LocalisationRemorque,3,0) -> Viemme Rond-Point | D43: =CONCATENATE(VLOOKUP($A43,LocalisationRemorque,6,0)," ► ",VLOOKUP($A43,LocalisationRemorque,5,0)) -> Waremme ► Huy
A44: 218 | B44: =VLOOKUP($A44,LocalisationRemorque,2,0) -> Oreye | C44: =VLOOKUP($A44,LocalisationRemorque,3,0) -> Carrefour Otrange/Vechmaal | D44: =CONCATENATE(VLOOKUP($A44,LocalisationRemorque,6,0)," ► ",VLOOKUP($A44,LocalisationRemorque,5,0)) -> Oreye ► Veechmaal
B45: =VLOOKUP($A45,LocalisationRemorque,2,0) -> Remorque non listée | C45: =VLOOKUP($A45,LocalisationRemorque,3,0) | D45: =CONCATENATE(VLOOKUP($A45,LocalisationRemorque,6,0)," ► ",VLOOKUP($A45,LocalisationRemorque,5,0)) -> ►
A46: 220 | B46: =VLOOKUP($A46,LocalisationRemorque,2,0) -> Theux | C46: =VLOOKUP($A46,LocalisationRemorque,3,0) -> Hautregard Haut | D46: =CONCATENATE(VLOOKUP($A46,LocalisationRemorque,6,0)," ► ",VLOOKUP($A46,LocalisationRemorque,5,0)) -> Aywaille ► Theux | BA46: Plopsa
A47: 221 | B47: =VLOOKUP($A47,LocalisationRemorque,2,0) -> Theux | C47: =VLOOKUP($A47,LocalisationRemorque,3,0) -> Hautregard Bas | D47: =CONCATENATE(VLOOKUP($A47,LocalisationRemorque,6,0)," ► ",VLOOKUP($A47,LocalisationRemorque,5,0)) -> Aywaille ► Spa | BA47: Plopsa
A48: 226 | B48: =VLOOKUP($A48,LocalisationRemorque,2,0) -> Theux | C48: =VLOOKUP($A48,LocalisationRemorque,3,0) -> La Reid | D48: =CONCATENATE(VLOOKUP($A48,LocalisationRemorque,6,0)," ► ",VLOOKUP($A48,LocalisationRemorque,5,0)) -> Aywaille ► Spa | BA48: Plopsa
A49: 222 | B49: =VLOOKUP($A49,LocalisationRemorque,2,0) -> Sprimont | C49: =VLOOKUP($A49,LocalisationRemorque,3,0) -> Sprimont - Theux | D49: =CONCATENATE(VLOOKUP($A49,LocalisationRemorque,6,0)," ► ",VLOOKUP($A49,LocalisationRemorque,5,0)) -> Sprimont ► Theux | BA49: Plopsa
A50: 224 | B50: =VLOOKUP($A50,LocalisationRemorque,2,0) -> Crisnee | C50: =VLOOKUP($A50,LocalisationRemorque,3,0) -> Station Ledouble | D50: =CONCATENATE(VLOOKUP($A50,LocalisationRemorque,6,0)," ► ",VLOOKUP($A50,LocalisationRemorque,5,0)) -> Saint-Trond ► Liege | BA50: Plopsa
...

Sheet DISPO
B1: 2027 | C1: Emplacement | D1: Direction | E1: Janvier | F1: Janvier | G1: Février | H1: Février | I1: Mars | J1: Mars | K1: Avril | L1: Avril | M1: Mai | N1: Mai | O1: Juin | P1: Juin | Q1: Juillet | R1: Juillet | S1: Août | T1: Août | U1: Septembre | V1: Septembre | W1: Octobre | X1: Octobre | Y1: Novembre | Z1: Novembre | AA1: Décembre | AB1: Décembre
A2: =Tableau!A2 | B2: =VLOOKUP($A2,LocalisationRemorque,2,0) -> Remorque non listée | C2: =VLOOKUP($A2,LocalisationRemorque,3,0) | D2: =CONCATENATE(VLOOKUP($A2,LocalisationRemorque,6,0)," ► ",VLOOKUP($A2,LocalisationRemorque,5,0)) -> ► | E2: =IF(ISBLANK(Tableau!$E$2), "LIBRE", "OCCUPÉ") -> LIBRE | F2: =IF(ISBLANK(Tableau!$G$2), "LIBRE", "OCCUPÉ") -> LIBRE | G2: =IF(ISBLANK(Tableau!$I$2), "LIBRE", "OCCUPÉ") -> LIBRE | H2: =IF(ISBLANK(Tableau!$K$2), "LIBRE", "OCCUPÉ") -> LIBRE | I2: =IF(ISBLANK(Tableau!$M$2), "LIBRE", "OCCUPÉ") -> LIBRE | J2: =IF(ISBLANK(Tableau!$O$2), "LIBRE", "OCCUPÉ") -> LIBRE | K2: =IF(ISBLANK(Tableau!$Q$2), "LIBRE", "OCCUPÉ") -> LIBRE | L2: =IF(ISBLANK(Tableau!$S$2), "LIBRE", "OCCUPÉ") -> LIBRE | M2: =IF(ISBLANK(Tableau!$U$2), "LIBRE", "OCCUPÉ") -> LIBRE | N2: =IF(ISBLANK(Tableau!$W$2), "LIBRE", "OCCUPÉ") -> LIBRE | O2: =IF(ISBLANK(Tableau!$Y$2), "LIBRE", "OCCUPÉ") -> LIBRE | P2: =IF(ISBLANK(Tableau!$AA$2), "LIBRE", "OCCUPÉ") -> LIBRE | Q2: =IF(ISBLANK(Tableau!$AC$2), "LIBRE", "OCCUPÉ") -> LIBRE | R2: =IF(ISBLANK(Tableau!$AE$2), "LIBRE", "OCCUPÉ") -> LIBRE | S2: =IF(ISBLANK(Tableau!$AG$2), "LIBRE", "OCCUPÉ") -> LIBRE | T2: =IF(ISBLANK(Tableau!$AI$2), "LIBRE", "OCCUPÉ") -> LIBRE | U2: =IF(ISBLANK(Tableau!$AK$2), "LIBRE", "OCCUPÉ") -> LIBRE | V2: =IF(ISBLANK(Tableau!$AM$2), "LIBRE", "OCCUPÉ") -> LIBRE | W2: =IF(ISBLANK(Tableau!$AO$2), "LIBRE", "OCCUPÉ") -> LIBRE | X2: =IF(ISBLANK(Tableau!$AQ$2), "LIBRE", "OCCUPÉ") -> LIBRE | Y2: =IF(ISBLANK(Tableau!$AS$2), "LIBRE", "OCCUPÉ") -> LIBRE | Z2: =IF(ISBLANK(Tableau!$AU$2), "LIBRE", "OCCUPÉ") -> LIBRE | AA2: =IF(ISBLANK(Tableau!$AW$2), "LIBRE", "OCCUPÉ") -> LIBRE | AB2: =IF(ISBLANK(Tableau!$AY$2), "LIBRE", "OCCUPÉ") -> LIBRE
A3: =Tableau!A3 -> 102 | B3: =VLOOKUP($A3,LocalisationRemorque,2,0) -> Nivelles | C3: =VLOOKUP($A3,LocalisationRemorque,3,0) -> Sud Thines | D3: =CONCATENATE(VLOOKUP($A3,LocalisationRemorque,6,0)," ► ",VLOOKUP($A3,LocalisationRemorque,5,0)) -> Nivelles ► Namur | E3: =IF(ISBLANK(Tableau!$E$3), "LIBRE", "OCCUPÉ") -> OCCUPÉ | F3: =IF(ISBLANK(Tableau!$G$3), "LIBRE", "OCCUPÉ") -> OCCUPÉ | G3: =IF(ISBLANK(Tableau!$I$3), "LIBRE", "OCCUPÉ") -> LIBRE | H3: =IF(ISBLANK(Tableau!$K$3), "LIBRE", "OCCUPÉ") -> LIBRE | I3: =IF(ISBLANK(Tableau!$M$3), "LIBRE", "OCCUPÉ") -> LIBRE | J3: =IF(ISBLANK(Tableau!$O$3), "LIBRE", "OCCUPÉ") -> LIBRE | K3: =IF(ISBLANK(Tableau!$Q$3), "LIBRE", "OCCUPÉ") -> LIBRE | L3: =IF(ISBLANK(Tableau!$S$3), "LIBRE", "OCCUPÉ") -> OCCUPÉ | M3: =IF(ISBLANK(Tableau!$U$3), "LIBRE", "OCCUPÉ") -> LIBRE | N3: =IF(ISBLANK(Tableau!$W$3), "LIBRE", "OCCUPÉ") -> OCCUPÉ | O3: =IF(ISBLANK(Tableau!$Y$3), "LIBRE", "OCCUPÉ") -> LIBRE | P3: =IF(ISBLANK(Tableau!$AA$3), "LIBRE", "OCCUPÉ") -> LIBRE | Q3: =IF(ISBLANK(Tableau!$AC$3), "LIBRE", "OCCUPÉ") -> OCCUPÉ | R3: =IF(ISBLANK(Tableau!$AE$3), "LIBRE", "OCCUPÉ") -> OCCUPÉ | S3: =IF(ISBLANK(Tableau!$AG$3), "LIBRE", "OCCUPÉ") -> LIBRE | T3: =IF(ISBLANK(Tableau!$AI$3), "LIBRE", "OCCUPÉ") -> LIBRE | U3: =IF(ISBLANK(Tableau!$AK$3), "LIBRE", "OCCUPÉ") -> OCCUPÉ | V3: =IF(ISBLANK(Tableau!$AM$3), "LIBRE", "OCCUPÉ") -> LIBRE | W3: =IF(ISBLANK(Tableau!$AO$3), "LIBRE", "OCCUPÉ") -> OCCUPÉ | X3: =IF(ISBLANK(Tableau!$AQ$3), "LIBRE", "OCCUPÉ") -> LIBRE | Y3: =IF(ISBLANK(Tableau!$AS$3), "LIBRE", "OCCUPÉ") -> LIBRE | Z3: =IF(ISBLANK(Tableau!$AU$3), "LIBRE", "OCCUPÉ") -> LIBRE | AA3: =IF(ISBLANK(Tableau!$AW$3), "LIBRE", "OCCUPÉ") -> OCCUPÉ | AB3: =IF(ISBLANK(Tableau!$AY$3), "LIBRE", "OCCUPÉ") -> LIBRE
A4: =Tableau!A4 | B4: =VLOOKUP($A4,LocalisationRemorque,2,0) -> Remorque non listée | C4: =VLOOKUP($A4,LocalisationRemorque,3,0) | D4: =CONCATENATE(VLOOKUP($A4,LocalisationRemorque,6,0)," ► ",VLOOKUP($A4,LocalisationRemorque,5,0)) -> ► | E4: =IF(ISBLANK(Tableau!$E$4), "LIBRE", "OCCUPÉ") -> LIBRE | F4: =IF(ISBLANK(Tableau!$G$4), "LIBRE", "OCCUPÉ") -> LIBRE | G4: =IF(ISBLANK(Tableau!$I$4), "LIBRE", "OCCUPÉ") -> LIBRE | H4: =IF(ISBLANK(Tableau!$K$4), "LIBRE", "OCCUPÉ") -> LIBRE | I4: =IF(ISBLANK(Tableau!$M$4), "LIBRE", "OCCUPÉ") -> LIBRE | J4: =IF(ISBLANK(Tableau!$O$4), "LIBRE", "OCCUPÉ") -> LIBRE | K4: =IF(ISBLANK(Tableau!$Q$4), "LIBRE", "OCCUPÉ") -> LIBRE | L4: =IF(ISBLANK(Tableau!$S$4), "LIBRE", "OCCUPÉ") -> LIBRE | M4: =IF(ISBLANK(Tableau!$U$4), "LIBRE", "OCCUPÉ") -> LIBRE | N4: =IF(ISBLANK(Tableau!$W$4), "LIBRE", "OCCUPÉ") -> LIBRE | O4: =IF(ISBLANK(Tableau!$Y$4), "LIBRE", "OCCUPÉ") -> LIBRE | P4: =IF(ISBLANK(Tableau!$AA$4), "LIBRE", "OCCUPÉ") -> LIBRE | Q4: =IF(ISBLANK(Tableau!$AC$4), "LIBRE", "OCCUPÉ") -> LIBRE | R4: =IF(ISBLANK(Tableau!$AE$4), "LIBRE", "OCCUPÉ") -> LIBRE | S4: =IF(ISBLANK(Tableau!$AG$4), "LIBRE", "OCCUPÉ") -> LIBRE | T4: =IF(ISBLANK(Tableau!$AI$4), "LIBRE", "OCCUPÉ") -> LIBRE | U4: =IF(ISBLANK(Tableau!$AK$4), "LIBRE", "OCCUPÉ") -> LIBRE | V4: =IF(ISBLANK(Tableau!$AM$4), "LIBRE", "OCCUPÉ") -> LIBRE | W4: =IF(ISBLANK(Tableau!$AO$4), "LIBRE", "OCCUPÉ") -> LIBRE | X4: =IF(ISBLANK(Tableau!$AQ$4), "LIBRE", "OCCUPÉ") -> LIBRE | Y4: =IF(ISBLANK(Tableau!$AS$4), "LIBRE", "OCCUPÉ") -> LIBRE | Z4: =IF(ISBLANK(Tableau!$AU$4), "LIBRE", "OCCUPÉ") -> LIBRE | AA4: =IF(ISBLANK(Tableau!$AW$4), "LIBRE", "OCCUPÉ") -> LIBRE | AB4: =IF(ISBLANK(Tableau!$AY$4), "LIBRE", "OCCUPÉ") -> LIBRE
A5: =Tableau!A5 -> 104 | B5: =VLOOKUP($A5,LocalisationRemorque,2,0) -> Ottignies | C5: =VLOOKUP($A5,LocalisationRemorque,3,0) -> Clinique | D5: =CONCATENATE(VLOOKUP($A5,LocalisationRemorque,6,0)," ► ",VLOOKUP($A5,LocalisationRemorque,5,0)) -> Rixensart ► Court-Saint-Etienne | E5: =IF(ISBLANK(Tableau!$E$5), "LIBRE", "OCCUPÉ") -> OCCUPÉ | F5: =IF(ISBLANK(Tableau!$G$5), "LIBRE", "OCCUPÉ") -> OCCUPÉ | G5: =IF(ISBLANK(Tableau!$I$5), "LIBRE", "OCCUPÉ") -> LIBRE | H5: =IF(ISBLANK(Tableau!$K$5), "LIBRE", "OCCUPÉ") -> LIBRE | I5: =IF(ISBLANK(Tableau!$M$5), "LIBRE", "OCCUPÉ") -> OCCUPÉ | J5: =IF(ISBLANK(Tableau!$O$5), "LIBRE", "OCCUPÉ") -> LIBRE | K5: =IF(ISBLANK(Tableau!$Q$5), "LIBRE", "OCCUPÉ") -> LIBRE | L5: =IF(ISBLANK(Tableau!$S$5), "LIBRE", "OCCUPÉ") -> LIBRE | M5: =IF(ISBLANK(Tableau!$U$5), "LIBRE", "OCCUPÉ") -> LIBRE | N5: =IF(ISBLANK(Tableau!$W$5), "LIBRE", "OCCUPÉ") -> LIBRE | O5: =IF(ISBLANK(Tableau!$Y$5), "LIBRE", "OCCUPÉ") -> OCCUPÉ | P5: =IF(ISBLANK(Tableau!$AA$5), "LIBRE", "OCCUPÉ") -> LIBRE | Q5: =IF(ISBLANK(Tableau!$AC$5), "LIBRE", "OCCUPÉ") -> LIBRE | R5: =IF(ISBLANK(Tableau!$AE$5), "LIBRE", "OCCUPÉ") -> LIBRE | S5: =IF(ISBLANK(Tableau!$AG$5), "LIBRE", "OCCUPÉ") -> LIBRE | T5: =IF(ISBLANK(Tableau!$AI$5), "LIBRE", "OCCUPÉ") -> LIBRE | U5: =IF(ISBLANK(Tableau!$AK$5), "LIBRE", "OCCUPÉ") -> OCCUPÉ | V5: =IF(ISBLANK(Tableau!$AM$5), "LIBRE", "OCCUPÉ") -> LIBRE | W5: =IF(ISBLANK(Tableau!$AO$5), "LIBRE", "OCCUPÉ") -> LIBRE | X5: =IF(ISBLANK(Tableau!$AQ$5), "LIBRE", "OCCUPÉ") -> LIBRE | Y5: =IF(ISBLANK(Tableau!$AS$5), "LIBRE", "OCCUPÉ") -> OCCUPÉ | Z5: =IF(ISBLANK(Tableau!$AU$5), "LIBRE", "OCCUPÉ") -> LIBRE | AA5: =IF(ISBLANK(Tableau!$AW$5), "LIBRE", "OCCUPÉ") -> LIBRE | AB5: =IF(ISBLANK(Tableau!$AY$5), "LIBRE", "OCCUPÉ") -> LIBRE
A6: =Tableau!A6 -> 105 | B6: =VLOOKUP($A6,LocalisationRemorque,2,0) -> Louvain-la-Neuve | C6: =VLOOKUP($A6,LocalisationRemorque,3,0) -> Corbais | D6: =CONCATENATE(VLOOKUP($A6,LocalisationRemorque,6,0)," ► ",VLOOKUP($A6,LocalisationRemorque,5,0)) -> LLN ► Gembloux | E6: =IF(ISBLANK(Tableau!$E$6), "LIBRE", "OCCUPÉ") -> OCCUPÉ | F6: =IF(ISBLANK(Tableau!$G$6), "LIBRE", "OCCUPÉ") -> LIBRE | G6: =IF(ISBLANK(Tableau!$I$6), "LIBRE", "OCCUPÉ") -> LIBRE | H6: =IF(ISBLANK(Tableau!$K$6), "LIBRE", "OCCUPÉ") -> LIBRE | I6: =IF(ISBLANK(Tableau!$M$6), "LIBRE", "OCCUPÉ") -> LIBRE | J6: =IF(ISBLANK(Tableau!$O$6), "LIBRE", "OCCUPÉ") -> LIBRE | K6: =IF(ISBLANK(Tableau!$Q$6), "LIBRE", "OCCUPÉ") -> LIBRE | L6: =IF(ISBLANK(Tableau!$S$6), "LIBRE", "OCCUPÉ") -> LIBRE | M6: =IF(ISBLANK(Tableau!$U$6), "LIBRE", "OCCUPÉ") -> LIBRE | N6: =IF(ISBLANK(Tableau!$W$6), "LIBRE", "OCCUPÉ") -> LIBRE | O6: =IF(ISBLANK(Tableau!$Y$6), "LIBRE", "OCCUPÉ") -> LIBRE | P6: =IF(ISBLANK(Tableau!$AA$6), "LIBRE", "OCCUPÉ") -> LIBRE | Q6: =IF(ISBLANK(Tableau!$AC$6), "LIBRE", "OCCUPÉ") -> OCCUPÉ | R6: =IF(ISBLANK(Tableau!$AE$6), "LIBRE", "OCCUPÉ") -> LIBRE | S6: =IF(ISBLANK(Tableau!$AG$6), "LIBRE", "OCCUPÉ") -> LIBRE | T6: =IF(ISBLANK(Tableau!$AI$6), "LIBRE", "OCCUPÉ") -> LIBRE | U6: =IF(ISBLANK(Tableau!$AK$6), "LIBRE", "OCCUPÉ") -> LIBRE | V6: =IF(ISBLANK(Tableau!$AM$6), "LIBRE", "OCCUPÉ") -> LIBRE | W6: =IF(ISBLANK(Tableau!$AO$6), "LIBRE", "OCCUPÉ") -> LIBRE | X6: =IF(ISBLANK(Tableau!$AQ$6), "LIBRE", "OCCUPÉ") -> LIBRE | Y6: =IF(ISBLANK(Tableau!$AS$6), "LIBRE", "OCCUPÉ") -> LIBRE | Z6: =IF(ISBLANK(Tableau!$AU$6), "LIBRE", "OCCUPÉ") -> LIBRE | AA6: =IF(ISBLANK(Tableau!$AW$6), "LIBRE", "OCCUPÉ") -> OCCUPÉ | AB6: =IF(ISBLANK(Tableau!$AY6), "LIBRE", "OCCUPÉ") -> LIBRE
A7: =Tableau!A7 -> 106 | B7: =VLOOKUP($A7,LocalisationRemorque,2,0) -> Wavre | C7: =VLOOKUP($A7,LocalisationRemorque,3,0) -> Grez-Doiceau 1 | D7: =CONCATENATE(VLOOKUP($A7,LocalisationRemorque,6,0)," ► ",VLOOKUP($A7,LocalisationRemorque,5,0)) -> Wavre ► Grez | E7: =IF(ISBLANK(Tableau!$E$7), "LIBRE", "OCCUPÉ") -> OCCUPÉ | F7: =IF(ISBLANK(Tableau!$G$7), "LIBRE", "OCCUPÉ") -> OCCUPÉ | G7: =IF(ISBLANK(Tableau!$I$7), "LIBRE", "OCCUPÉ") -> LIBRE | H7: =IF(ISBLANK(Tableau!$K$7), "LIBRE", "OCCUPÉ") -> LIBRE | I7: =IF(ISBLANK(Tableau!$M$7), "LIBRE", "OCCUPÉ") -> OCCUPÉ | J7: =IF(ISBLANK(Tableau!$O$7), "LIBRE", "OCCUPÉ") -> LIBRE | K7: =IF(ISBLANK(Tableau!$Q$7), "LIBRE", "OCCUPÉ") -> LIBRE | L7: =IF(ISBLANK(Tableau!$S$7), "LIBRE", "OCCUPÉ") -> LIBRE | M7: =IF(ISBLANK(Tableau!$U$7), "LIBRE", "OCCUPÉ") -> LIBRE | N7: =IF(ISBLANK(Tableau!$W$7), "LIBRE", "OCCUPÉ") -> LIBRE | O7: =IF(ISBLANK(Tableau!$Y$7), "LIBRE", "OCCUPÉ") -> OCCUPÉ | P7: =IF(ISBLANK(Tableau!$AA$7), "LIBRE", "OCCUPÉ") -> LIBRE | Q7: =IF(ISBLANK(Tableau!$AC$7), "LIBRE", "OCCUPÉ") -> LIBRE | R7: =IF(ISBLANK(Tableau!$AE$7), "LIBRE", "OCCUPÉ") -> LIBRE | S7: =IF(ISBLANK(Tableau!$AG$7), "LIBRE", "OCCUPÉ") -> LIBRE | T7: =IF(ISBLANK(Tableau!$AI$7), "LIBRE", "OCCUPÉ") -> LIBRE | U7: =IF(ISBLANK(Tableau!$AK$7), "LIBRE", "OCCUPÉ") -> OCCUPÉ | V7: =IF(ISBLANK(Tableau!$AM$7), "LIBRE", "OCCUPÉ") -> LIBRE | W7: =IF(ISBLANK(Tableau!$AO$7), "LIBRE", "OCCUPÉ") -> LIBRE | X7: =IF(ISBLANK(Tableau!$AQ$7), "LIBRE", "OCCUPÉ") -> LIBRE | Y7: =IF(ISBLANK(Tableau!$AS$7), "LIBRE", "OCCUPÉ") -> OCCUPÉ | Z7: =IF(ISBLANK(Tableau!$AU$7), "LIBRE", "OCCUPÉ") -> LIBRE | AA7: =IF(ISBLANK(Tableau!$AW$7), "LIBRE", "OCCUPÉ") -> LIBRE | AB7: =IF(ISBLANK(Tableau!$AY7), "LIBRE", "OCCUPÉ") -> LIBRE
A8: =Tableau!A8 -> 107 | B8: =VLOOKUP($A8,LocalisationRemorque,2,0) -> Wavre | C8: =VLOOKUP($A8,LocalisationRemorque,3,0) -> Grez-Doiceau 2 | D8: =CONCATENATE(VLOOKUP($A8,LocalisationRemorque,6,0)," ► ",VLOOKUP($A8,LocalisationRemorque,5,0)) -> LLN ► Wavre | E8: =IF(ISBLANK(Tableau!$E$8), "LIBRE", "OCCUPÉ") -> OCCUPÉ | F8: =IF(ISBLANK(Tableau!$G$8), "LIBRE", "OCCUPÉ") -> LIBRE | G8: =IF(ISBLANK(Tableau!$I$8), "LIBRE", "OCCUPÉ") -> LIBRE | H8: =IF(ISBLANK(Tableau!$K$8), "LIBRE", "OCCUPÉ") -> LIBRE | I8: =IF(ISBLANK(Tableau!$M$8), "LIBRE", "OCCUPÉ") -> OCCUPÉ | J8: =IF(ISBLANK(Tableau!$O$8), "LIBRE", "OCCUPÉ") -> LIBRE | K8: =IF(ISBLANK(Tableau!$Q$8), "LIBRE", "OCCUPÉ") -> LIBRE | L8: =IF(ISBLANK(Tableau!$S$8), "LIBRE", "OCCUPÉ") -> LIBRE | M8: =IF(ISBLANK(Tableau!$U$8), "LIBRE", "OCCUPÉ") -> LIBRE | N8: =IF(ISBLANK(Tableau!$W$8), "LIBRE", "OCCUPÉ") -> LIBRE | O8: =IF(ISBLANK(Tableau!$Y$8), "LIBRE", "OCCUPÉ") -> OCCUPÉ | P8: =IF(ISBLANK(Tableau!$AA$8), "LIBRE", "OCCUPÉ") -> LIBRE | Q8: =IF(ISBLANK(Tableau!$AC$8), "LIBRE", "OCCUPÉ") -> LIBRE | R8: =IF(ISBLANK(Tableau!$AE$8), "LIBRE", "OCCUPÉ") -> LIBRE | S8: =IF(ISBLANK(Tableau!$AG$8), "LIBRE", "OCCUPÉ") -> LIBRE | T8: =IF(ISBLANK(Tableau!$AI$8), "LIBRE", "OCCUPÉ") -> LIBRE | U8: =IF(ISBLANK(Tableau!$AK$8), "LIBRE", "OCCUPÉ") -> OCCUPÉ | V8: =IF(ISBLANK(Tableau!$AM$8), "LIBRE", "OCCUPÉ") -> LIBRE | W8: =IF(ISBLANK(Tableau!$AO$8), "LIBRE", "OCCUPÉ") -> LIBRE | X8: =IF(ISBLANK(Tableau!$AQ$8), "LIBRE", "OCCUPÉ") -> LIBRE | Y8: =IF(ISBLANK(Tableau!$AS$8), "LIBRE", "OCCUPÉ") -> OCCUPÉ | Z8: =IF(ISBLANK(Tableau!$AU$8), "LIBRE", "OCCUPÉ") -> LIBRE | AA8: =IF(ISBLANK(Tableau!$AW$8), "LIBRE", "OCCUPÉ") -> LIBRE | AB8: =IF(ISBLANK(Tableau!$AY8), "LIBRE", "OCCUPÉ") -> LIBRE
A9: =Tableau!A9 -> 108 | B9: =VLOOKUP($A9,LocalisationRemorque,2,0) -> Wavre | C9: =VLOOKUP($A9,LocalisationRemorque,3,0) -> Grez-Doiceau 3 | D9: =CONCATENATE(VLOOKUP($A9,LocalisationRemorque,6,0)," ► ",VLOOKUP($A9,LocalisationRemorque,5,0)) -> Wavre ► Grez | E9: =IF(ISBLANK(Tableau!$E$9), "LIBRE", "OCCUPÉ") -> OCCUPÉ | F9: =IF(ISBLANK(Tableau!$G$9), "LIBRE", "OCCUPÉ") -> LIBRE | G9: =IF(ISBLANK(Tableau!$I$9), "LIBRE", "OCCUPÉ") -> LIBRE | H9: =IF(ISBLANK(Tableau!$K$9), "LIBRE", "OCCUPÉ") -> LIBRE | I9: =IF(ISBLANK(Tableau!$M$9), "LIBRE", "OCCUPÉ") -> OCCUPÉ | J9: =IF(ISBLANK(Tableau!$O$9), "LIBRE", "OCCUPÉ") -> LIBRE | K9: =IF(ISBLANK(Tableau!$Q$9), "LIBRE", "OCCUPÉ") -> LIBRE | L9: =IF(ISBLANK(Tableau!$S$9), "LIBRE", "OCCUPÉ") -> LIBRE | M9: =IF(ISBLANK(Tableau!$U$9), "LIBRE", "OCCUPÉ") -> LIBRE | N9: =IF(ISBLANK(Tableau!$W$9), "LIBRE", "OCCUPÉ") -> LIBRE | O9: =IF(ISBLANK(Tableau!$Y$9), "LIBRE", "OCCUPÉ") -> OCCUPÉ | P9: =IF(ISBLANK(Tableau!$AA$9), "LIBRE", "OCCUPÉ") -> LIBRE | Q9: =IF(ISBLANK(Tableau!$AC$9), "LIBRE", "OCCUPÉ") -> OCCUPÉ | R9: =IF(ISBLANK(Tableau!$AE$9), "LIBRE", "OCCUPÉ") -> LIBRE | S9: =IF(ISBLANK(Tableau!$AG$9), "LIBRE", "OCCUPÉ") -> LIBRE | T9: =IF(ISBLANK(Tableau!$AI$9), "LIBRE", "OCCUPÉ") -> LIBRE | U9: =IF(ISBLANK(Tableau!$AK$9), "LIBRE", "OCCUPÉ") -> OCCUPÉ | V9: =IF(ISBLANK(Tableau!$AM$9), "LIBRE", "OCCUPÉ") -> LIBRE | W9: =IF(ISBLANK(Tableau!$AO$9), "LIBRE", "OCCUPÉ") -> LIBRE | X9: =IF(ISBLANK(Tableau!$AQ$9), "LIBRE", "OCCUPÉ") -> LIBRE | Y9: =IF(ISBLANK(Tableau!$AS$9), "LIBRE", "OCCUPÉ") -> OCCUPÉ | Z9: =IF(ISBLANK(Tableau!$AU$9), "LIBRE", "OCCUPÉ") -> LIBRE | AA9: =IF(ISBLANK(Tableau!$AW$9), "LIBRE", "OCCUPÉ") -> LIBRE | AB9: =IF(ISBLANK(Tableau!$AY9), "LIBRE", "OCCUPÉ") -> LIBRE
A10: =Tableau!A10 -> 109 | B10: =VLOOKUP($A10,LocalisationRemorque,2,0) -> Jodoigne | C10: =VLOOKUP($A10,LocalisationRemorque,3,0) -> Mélin | D10: =CONCATENATE(VLOOKUP($A10,LocalisationRemorque,6,0)," ► ",VLOOKUP($A10,LocalisationRemorque,5,0)) -> Jodoigne ► Beauvechain | E10: =IF(ISBLANK(Tableau!$E$10), "LIBRE", "OCCUPÉ") -> LIBRE | F10: =IF(ISBLANK(Tableau!$G$10), "LIBRE", "OCCUPÉ") -> LIBRE | G10: =IF(ISBLANK(Tableau!$I$10), "LIBRE", "OCCUPÉ") -> LIBRE | H10: =IF(ISBLANK(Tableau!$K$10), "LIBRE", "OCCUPÉ") -> LIBRE | I10: =IF(ISBLANK(Tableau!$M$10), "LIBRE", "OCCUPÉ") -> LIBRE | J10: =IF(ISBLANK(Tableau!$O$10), "LIBRE", "OCCUPÉ") -> LIBRE | K10: =IF(ISBLANK(Tableau!$Q$10), "LIBRE", "OCCUPÉ") -> LIBRE | L10: =IF(ISBLANK(Tableau!$S$10), "LIBRE", "OCCUPÉ") -> LIBRE | M10: =IF(ISBLANK(Tableau!$U$10), "LIBRE", "OCCUPÉ") -> LIBRE | N10: =IF(ISBLANK(Tableau!$W$10), "LIBRE", "OCCUPÉ") -> LIBRE | O10: =IF(ISBLANK(Tableau!$Y$10), "LIBRE", "OCCUPÉ") -> LIBRE | P10: =IF(ISBLANK(Tableau!$AA$10), "LIBRE", "OCCUPÉ") -> LIBRE | Q10: =IF(ISBLANK(Tableau!$AC$11), "LIBRE", "OCCUPÉ") -> LIBRE | R10: =IF(ISBLANK(Tableau!$AE$10), "LIBRE", "OCCUPÉ") -> LIBRE | S10: =IF(ISBLANK(Tableau!$AG$10), "LIBRE", "OCCUPÉ") -> LIBRE | T10: =IF(ISBLANK(Tableau!$AI$10), "LIBRE", "OCCUPÉ") -> LIBRE | U10: =IF(ISBLANK(Tableau!$AK$10), "LIBRE", "OCCUPÉ") -> LIBRE | V10: =IF(ISBLANK(Tableau!$AM$10), "LIBRE", "OCCUPÉ") -> LIBRE | W10: =IF(ISBLANK(Tableau!$AO$10), "LIBRE", "OCCUPÉ") -> LIBRE | X10: =IF(ISBLANK(Tableau!$AQ$10), "LIBRE", "OCCUPÉ") -> LIBRE | Y10: =IF(ISBLANK(Tableau!$AS$10), "LIBRE", "OCCUPÉ") -> LIBRE | Z10: =IF(ISBLANK(Tableau!$AU$10), "LIBRE", "OCCUPÉ") -> LIBRE | AA10: =IF(ISBLANK(Tableau!$AW$10), "LIBRE", "OCCUPÉ") -> LIBRE | AB10: =IF(ISBLANK(Tableau!$AY10), "LIBRE", "OCCUPÉ") -> LIBRE
A11: =Tableau!A11 -> 110 | B11: =VLOOKUP($A11,LocalisationRemorque,2,0) -> Jodoigne | C11: =VLOOKUP($A11,LocalisationRemorque,3,0) -> Entree Jodoigne | D11: =CONCATENATE(VLOOKUP($A11,LocalisationRemorque,6,0)," ► ",VLOOKUP($A11,LocalisationRemorque,5,0)) -> Jodoigne ► Tirlemont | E11: =IF(ISBLANK(Tableau!$E$11), "LIBRE", "OCCUPÉ") -> LIBRE | F11: =IF(ISBLANK(Tableau!$G$11), "LIBRE", "OCCUPÉ") -> LIBRE | G11: =IF(ISBLANK(Tableau!$I$11), "LIBRE", "OCCUPÉ") -> LIBRE | H11: =IF(ISBLANK(Tableau!$K$11), "LIBRE", "OCCUPÉ") -> LIBRE | I11: =IF(ISBLANK(Tableau!$M$11), "LIBRE", "OCCUPÉ") -> LIBRE | J11: =IF(ISBLANK(Tableau!$O$11), "LIBRE", "OCCUPÉ") -> LIBRE | K11: =IF(ISBLANK(Tableau!$Q$11), "LIBRE", "OCCUPÉ") -> LIBRE | L11: =IF(ISBLANK(Tableau!$S$11), "LIBRE", "OCCUPÉ") -> LIBRE | M11: =IF(ISBLANK(Tableau!$U$11), "LIBRE", "OCCUPÉ") -> LIBRE | N11: =IF(ISBLANK(Tableau!$W$11), "LIBRE", "OCCUPÉ") -> LIBRE | O11: =IF(ISBLANK(Tableau!$Y$11), "LIBRE", "OCCUPÉ") -> LIBRE | P11: =IF(ISBLANK(Tableau!$AA$11), "LIBRE", "OCCUPÉ") -> LIBRE | Q11: =IF(ISBLANK(#REF!), "LIBRE", "OCCUPÉ") -> OCCUPÉ | R11: =IF(ISBLANK(Tableau!$AE$11), "LIBRE", "OCCUPÉ") -> LIBRE | S11: =IF(ISBLANK(Tableau!$AG$11), "LIBRE", "OCCUPÉ") -> LIBRE | T11: =IF(ISBLANK(Tableau!$AI$11), "LIBRE", "OCCUPÉ") -> LIBRE | U11: =IF(ISBLANK(Tableau!$AK$11), "LIBRE", "OCCUPÉ") -> LIBRE | V11: =IF(ISBLANK(Tableau!$AM$11), "LIBRE", "OCCUPÉ") -> LIBRE | W11: =IF(ISBLANK(Tableau!$AO$11), "LIBRE", "OCCUPÉ") -> LIBRE | X11: =IF(ISBLANK(Tableau!$AQ$11), "LIBRE", "OCCUPÉ") -> LIBRE | Y11: =IF(ISBLANK(Tableau!$AS$11), "LIBRE", "OCCUPÉ") -> LIBRE | Z11: =IF(ISBLANK(Tableau!$AU$11), "LIBRE", "OCCUPÉ") -> LIBRE | AA11: =IF(ISBLANK(Tableau!$AW$11), "LIBRE", "OCCUPÉ") -> LIBRE | AB11: =IF(ISBLANK(Tableau!$AY11), "LIBRE", "OCCUPÉ") -> LIBRE
A12: =Tableau!A12 -> 111 | B12: =VLOOKUP($A12,LocalisationRemorque,2,0) -> Beauvechain | C12: =VLOOKUP($A12,LocalisationRemorque,3,0) -> Nodebais | D12: =CONCATENATE(VLOOKUP($A12,LocalisationRemorque,6,0)," ► ",VLOOKUP($A12,LocalisationRemorque,5,0)) -> Éghezée ► Hamme | E12: =IF(ISBLANK(Tableau!$E$12), "LIBRE", "OCCUPÉ") -> OCCUPÉ | F12: =IF(ISBLANK(Tableau!$G$12), "LIBRE", "OCCUPÉ") -> LIBRE | G12: =IF(ISBLANK(Tableau!$I$12), "LIBRE", "OCCUPÉ") -> LIBRE | H12: =IF(ISBLANK(Tableau!$K$12), "LIBRE", "OCCUPÉ") -> LIBRE | I12: =IF(ISBLANK(Tableau!$M$12), "LIBRE", "OCCUPÉ") -> OCCUPÉ | J12: =IF(ISBLANK(Tableau!$O$12), "LIBRE", "OCCUPÉ") -> LIBRE | K12: =IF(ISBLANK(Tableau!$Q$12), "LIBRE", "OCCUPÉ") -> LIBRE | L12: =IF(ISBLANK(Tableau!$S$12), "LIBRE", "OCCUPÉ") -> LIBRE | M12: =IF(ISBLANK(Tableau!$U$12), "LIBRE", "OCCUPÉ") -> LIBRE | N12: =IF(ISBLANK(Tableau!$W$12), "LIBRE", "OCCUPÉ") -> LIBRE | O12: =IF(ISBLANK(Tableau!$Y$12), "LIBRE", "OCCUPÉ") -> OCCUPÉ | P12: =IF(ISBLANK(Tableau!$AA$12), "LIBRE", "OCCUPÉ") -> LIBRE | Q12: =IF(ISBLANK(Tableau!$AC$12), "LIBRE", "OCCUPÉ") -> OCCUPÉ | R12: =IF(ISBLANK(Tableau!$AE$12), "LIBRE", "OCCUPÉ") -> LIBRE | S12: =IF(ISBLANK(Tableau!$AG$12), "LIBRE", "OCCUPÉ") -> LIBRE | T12: =IF(ISBLANK(Tableau!$AI$12), "LIBRE", "OCCUPÉ") -> LIBRE | U12: =IF(ISBLANK(Tableau!$AK$12), "LIBRE", "OCCUPÉ") -> OCCUPÉ | V12: =IF(ISBLANK(Tableau!$AM$12), "LIBRE", "OCCUPÉ") -> LIBRE | W12: =IF(ISBLANK(Tableau!$AO$12), "LIBRE", "OCCUPÉ") -> LIBRE | X12: =IF(ISBLANK(Tableau!$AQ$12), "LIBRE", "OCCUPÉ") -> LIBRE | Y12: =IF(ISBLANK(Tableau!$AS$12), "LIBRE", "OCCUPÉ") -> OCCUPÉ | Z12: =IF(ISBLANK(Tableau!$AU$12), "LIBRE", "OCCUPÉ") -> LIBRE | AA12: =IF(ISBLANK(Tableau!$AW$12), "LIBRE", "OCCUPÉ") -> LIBRE | AB12: =IF(ISBLANK(Tableau!$AY12), "LIBRE", "OCCUPÉ") -> LIBRE
A13: =Tableau!A13 -> 112 | B13: =VLOOKUP($A13,LocalisationRemorque,2,0) -> Incourt | C13: =VLOOKUP($A13,LocalisationRemorque,3,0) -> Incourt | D13: =CONCATENATE(VLOOKUP($A13,LocalisationRemorque,6,0)," ► ",VLOOKUP($A13,LocalisationRemorque,5,0)) -> Louvain ► Éghezée | E13: =IF(ISBLANK(Tableau!$E$13), "LIBRE", "OCCUPÉ") -> LIBRE | F13: =IF(ISBLANK(Tableau!$G$13), "LIBRE", "OCCUPÉ") -> LIBRE | G13: =IF(ISBLANK(Tableau!$I$13), "LIBRE", "OCCUPÉ") -> LIBRE | H13: =IF(ISBLANK(Tableau!$K$13), "LIBRE", "OCCUPÉ") -> LIBRE | I13: =IF(ISBLANK(Tableau!$M$13), "LIBRE", "OCCUPÉ") -> LIBRE | J13: =IF(ISBLANK(Tableau!$O$13), "LIBRE", "OCCUPÉ") -> LIBRE | K13: =IF(ISBLANK(Tableau!$Q$13), "LIBRE", "OCCUPÉ") -> LIBRE | L13: =IF(ISBLANK(Tableau!$S$13), "LIBRE", "OCCUPÉ") -> LIBRE | M13: =IF(ISBLANK(Tableau!$U$13), "LIBRE", "OCCUPÉ") -> LIBRE | N13: =IF(ISBLANK(Tableau!$W$13), "LIBRE", "OCCUPÉ") -> LIBRE | O13: =IF(ISBLANK(Tableau!$Y$13), "LIBRE", "OCCUPÉ") -> LIBRE | P13: =IF(ISBLANK(Tableau!$AA$13), "LIBRE", "OCCUPÉ") -> LIBRE | Q13: =IF(ISBLANK(Tableau!$AC$13), "LIBRE", "OCCUPÉ") -> LIBRE | R13: =IF(ISBLANK(Tableau!$AE$13), "LIBRE", "OCCUPÉ") -> LIBRE | S13: =IF(ISBLANK(Tableau!$AG$13), "LIBRE", "OCCUPÉ") -> LIBRE | T13: =IF(ISBLANK(Tableau!$AI$13), "LIBRE", "OCCUPÉ") -> LIBRE | U13: =IF(ISBLANK(Tableau!$AK$13), "LIBRE", "OCCUPÉ") -> LIBRE | V13: =IF(ISBLANK(Tableau!$AM$13), "LIBRE", "OCCUPÉ") -> LIBRE | W13: =IF(ISBLANK(Tableau!$AO$13), "LIBRE", "OCCUPÉ") -> LIBRE | X13: =IF(ISBLANK(Tableau!$AQ$13), "LIBRE", "OCCUPÉ") -> LIBRE | Y13: =IF(ISBLANK(Tableau!$AS$13), "LIBRE", "OCCUPÉ") -> LIBRE | Z13: =IF(ISBLANK(Tableau!$AU$13), "LIBRE", "OCCUPÉ") -> LIBRE | AA13: =IF(ISBLANK(Tableau!$AW$13), "LIBRE", "OCCUPÉ") -> LIBRE | AB13: =IF(ISBLANK(Tableau!$AY13), "LIBRE", "OCCUPÉ") -> LIBRE
A14: =Tableau!A14 -> 113 | B14: =VLOOKUP($A14,LocalisationRemorque,2,0) -> Perwez | C14: =VLOOKUP($A14,LocalisationRemorque,3,0) -> Perwez | D14: =CONCATENATE(VLOOKUP($A14,LocalisationRemorque,6,0)," ► ",VLOOKUP($A14,LocalisationRemorque,5,0)) -> Jodoigne ► E411 | E14: =IF(ISBLANK(Tableau!$E$14), "LIBRE", "OCCUPÉ") -> LIBRE | F14: =IF(ISBLANK(Tableau!$G$14), "LIBRE", "OCCUPÉ") -> LIBRE | G14: =IF(ISBLANK(Tableau!$I$14), "LIBRE", "OCCUPÉ") -> LIBRE | H14: =IF(ISBLANK(Tableau!$K$14), "LIBRE", "OCCUPÉ") -> LIBRE | I14: =IF(ISBLANK(Tableau!$M$14), "LIBRE", "OCCUPÉ") -> LIBRE | J14: =IF(ISBLANK(Tableau!$O$14), "LIBRE", "OCCUPÉ") -> LIBRE | K14: =IF(ISBLANK(Tableau!$Q$14), "LIBRE", "OCCUPÉ") -> LIBRE | L14: =IF(ISBLANK(Tableau!$S$14), "LIBRE", "OCCUPÉ") -> LIBRE | M14: =IF(ISBLANK(Tableau!$U$14), "LIBRE", "OCCUPÉ") -> LIBRE | N14: =IF(ISBLANK(Tableau!$W$14), "LIBRE", "OCCUPÉ") -> LIBRE | O14: =IF(ISBLANK(Tableau!$Y$14), "LIBRE", "OCCUPÉ") -> LIBRE | P14: =IF(ISBLANK(Tableau!$AA$14), "LIBRE", "OCCUPÉ") -> LIBRE | Q14: =IF(ISBLANK(Tableau!$AC$14), "LIBRE", "OCCUPÉ") -> LIBRE | R14: =IF(ISBLANK(Tableau!$AE$14), "LIBRE", "OCCUPÉ") -> LIBRE | S14: =IF(ISBLANK(Tableau!$AG$14), "LIBRE", "OCCUPÉ") -> LIBRE | T14: =IF(ISBLANK(Tableau!$AI$14), "LIBRE", "OCCUPÉ") -> LIBRE | U14: =IF(ISBLANK(Tableau!$AK$14), "LIBRE", "OCCUPÉ") -> LIBRE | V14: =IF(ISBLANK(Tableau!$AM$14), "LIBRE", "OCCUPÉ") -> LIBRE | W14: =IF(ISBLANK(Tableau!$AO$14), "LIBRE", "OCCUPÉ") -> LIBRE | X14: =IF(ISBLANK(Tableau!$AQ$14), "LIBRE", "OCCUPÉ") -> LIBRE | Y14: =IF(ISBLANK(Tableau!$AS$14), "LIBRE", "OCCUPÉ") -> LIBRE | Z14: =IF(ISBLANK(Tableau!$AU$14), "LIBRE", "OCCUPÉ") -> LIBRE | AA14: =IF(ISBLANK(Tableau!$AW$14), "LIBRE", "OCCUPÉ") -> LIBRE | AB14: =IF(ISBLANK(Tableau!$AY14), "LIBRE", "OCCUPÉ") -> LIBRE
A15: =Tableau!A15 -> 114 | B15: =VLOOKUP($A15,LocalisationRemorque,2,0) -> Perwez | C15: =VLOOKUP($A15,LocalisationRemorque,3,0) -> Sortie E411 | D15: =CONCATENATE(VLOOKUP($A15,LocalisationRemorque,6,0)," ► ",VLOOKUP($A15,LocalisationRemorque,5,0)) -> E411 ► Jodoigne
A16: =Tableau!A16 | AB16: =IF(ISBLANK(Tableau!$AY16), "LIBRE", "OCCUPÉ") -> LIBRE
A17: =Tableau!A17 | AB17: =IF(ISBLANK(Tableau!$AY17), "LIBRE", "OCCUPÉ") -> LIBRE
A18: =Tableau!A18 | AB18: =IF(ISBLANK(Tableau!$AY18), "LIBRE", "OCCUPÉ") -> LIBRE
A19: =Tableau!A19 | AB19: =IF(ISBLANK(Tableau!$AY19), "LIBRE", "OCCUPÉ") -> LIBRE
A20: =Tableau!A20 | AB20: =IF(ISBLANK(Tableau!$AY20), "LIBRE", "OCCUPÉ") -> LIBRE
A21: =Tableau!A21 | AB21: =IF(ISBLANK(Tableau!$AY21), "LIBRE", "OCCUPÉ") -> LIBRE
A22: =Tableau!A22 | AB22: =IF(ISBLANK(Tableau!$AY22), "LIBRE", "OCCUPÉ") -> LIBRE
A23: =Tableau!A23 | AB23: =IF(ISBLANK(Tableau!$AY23), "LIBRE", "OCCUPÉ") -> LIBRE
A24: =Tableau!A24 | AB24: =IF(ISBLANK(Tableau!$AY24), "LIBRE", "OCCUPÉ") -> LIBRE
A25: =Tableau!A25 | AB25: =IF(ISBLANK(Tableau!$AY25), "LIBRE", "OCCUPÉ") -> LIBRE
A26: =Tableau!A26 -> 201 | B26: =VLOOKUP($A26,LocalisationRemorque,2,0) -> Hannut | C26: =VLOOKUP($A26,LocalisationRemorque,3,0) -> Hannut-Saint Trond | D26: =CONCATENATE(VLOOKUP($A26,LocalisationRemorque,6,0)," ► ",VLOOKUP($A26,LocalisationRemorque,5,0)) -> Hannut ► Saint-Trond | E26: =IF(ISBLANK(Tableau!$E$26), "LIBRE", "OCCUPÉ") -> LIBRE | F26: =IF(ISBLANK(Tableau!$G$26), "LIBRE", "OCCUPÉ") -> LIBRE | G26: =IF(ISBLANK(Tableau!$I$26), "LIBRE", "OCCUPÉ") -> LIBRE | H26: =IF(ISBLANK(Tableau!$K$26), "LIBRE", "OCCUPÉ") -> LIBRE | I26: =IF(ISBLANK(Tableau!$M$26), "LIBRE", "OCCUPÉ") -> LIBRE | J26: =IF(ISBLANK(Tableau!$O$26), "LIBRE", "OCCUPÉ") -> LIBRE | K26: =IF(ISBLANK(Tableau!$Q$26), "LIBRE", "OCCUPÉ") -> LIBRE | L26: =IF(ISBLANK(Tableau!$S$26), "LIBRE", "OCCUPÉ") -> LIBRE | M26: =IF(ISBLANK(Tableau!$U$26), "LIBRE", "OCCUPÉ") -> LIBRE | N26: =IF(ISBLANK(Tableau!$W$26), "LIBRE", "OCCUPÉ") -> LIBRE | O26: =IF(ISBLANK(Tableau!$Y$26), "LIBRE", "OCCUPÉ") -> LIBRE | P26: =IF(ISBLANK(Tableau!$AA$26), "LIBRE", "OCCUPÉ") -> LIBRE | Q26: =IF(ISBLANK(Tableau!$AC$26), "LIBRE", "OCCUPÉ") -> LIBRE | R26: =IF(ISBLANK(Tableau!$AE$26), "LIBRE", "OCCUPÉ") -> LIBRE | S26: =IF(ISBLANK(Tableau!$AG$26), "LIBRE", "OCCUPÉ") -> LIBRE | T26: =IF(ISBLANK(Tableau!$AI$26), "LIBRE", "OCCUPÉ") -> LIBRE | U26: =IF(ISBLANK(Tableau!$AK$26), "LIBRE", "OCCUPÉ") -> LIBRE | V26: =IF(ISBLANK(Tableau!$AM$26), "LIBRE", "OCCUPÉ") -> LIBRE | W26: =IF(ISBLANK(Tableau!$AO$26), "LIBRE", "OCCUPÉ") -> LIBRE | X26: =IF(ISBLANK(Tableau!$AQ$26), "LIBRE", "OCCUPÉ") -> LIBRE | Y26: =IF(ISBLANK(Tableau!$AS$26), "LIBRE", "OCCUPÉ") -> LIBRE | Z26: =IF(ISBLANK(Tableau!$AU$26), "LIBRE", "OCCUPÉ") -> LIBRE | AA26: =IF(ISBLANK(Tableau!$AW$26), "LIBRE", "OCCUPÉ") -> LIBRE | AB26: =IF(ISBLANK(Tableau!$AY26), "LIBRE", "OCCUPÉ") -> LIBRE
A27: =Tableau!A27 -> 202 | B27: =VLOOKUP($A27,LocalisationRemorque,2,0) -> Hannut | C27: =VLOOKUP($A27,LocalisationRemorque,3,0) -> Braives | D27: =CONCATENATE(VLOOKUP($A27,LocalisationRemorque,6,0)," ► ",VLOOKUP($A27,LocalisationRemorque,5,0)) -> Hannut ► E42 | E27: =IF(ISBLANK(Tableau!$E$27), "LIBRE", "OCCUPÉ") -> LIBRE | F27: =IF(ISBLANK(Tableau!$G$27), "LIBRE", "OCCUPÉ") -> LIBRE | G27: =IF(ISBLANK(Tableau!$I$27), "LIBRE", "OCCUPÉ") -> LIBRE | H27: =IF(ISBLANK(Tableau!$K$27), "LIBRE", "OCCUPÉ") -> LIBRE | I27: =IF(ISBLANK(Tableau!$M$27), "LIBRE", "OCCUPÉ") -> LIBRE | J27: =IF(ISBLANK(Tableau!$O$27), "LIBRE", "OCCUPÉ") -> LIBRE | K27: =IF(ISBLANK(Tableau!$Q$27), "LIBRE", "OCCUPÉ") -> LIBRE | L27: =IF(ISBLANK(Tableau!$S$27), "LIBRE", "OCCUPÉ") -> LIBRE | M27: =IF(ISBLANK(Tableau!$U$27), "LIBRE", "OCCUPÉ") -> LIBRE | N27: =IF(ISBLANK(Tableau!$W$27), "LIBRE", "OCCUPÉ") -> LIBRE | O27: =IF(ISBLANK(Tableau!$Y$27), "LIBRE", "OCCUPÉ") -> LIBRE | P27: =IF(ISBLANK(Tableau!$AA$27), "LIBRE", "OCCUPÉ") -> LIBRE | Q27: =IF(ISBLANK(Tableau!$AC$27), "LIBRE", "OCCUPÉ") -> LIBRE | R27: =IF(ISBLANK(Tableau!$AE$27), "LIBRE", "OCCUPÉ") -> LIBRE | S27: =IF(ISBLANK(Tableau!$AG$27), "LIBRE", "OCCUPÉ") -> LIBRE | T27: =IF(ISBLANK(Tableau!$AI$27), "LIBRE", "OCCUPÉ") -> LIBRE | U27: =IF(ISBLANK(Tableau!$AK$27), "LIBRE", "OCCUPÉ") -> LIBRE | V27: =IF(ISBLANK(Tableau!$AM$27), "LIBRE", "OCCUPÉ") -> LIBRE | W27: =IF(ISBLANK(Tableau!$AO$27), "LIBRE", "OCCUPÉ") -> LIBRE | X27: =IF(ISBLANK(Tableau!$AQ$27), "LIBRE", "OCCUPÉ") -> LIBRE | Y27: =IF(ISBLANK(Tableau!$AS$27), "LIBRE", "OCCUPÉ") -> LIBRE | Z27: =IF(ISBLANK(Tableau!$AU$27), "LIBRE", "OCCUPÉ") -> LIBRE | AA27: =IF(ISBLANK(Tableau!$AW$27), "LIBRE", "OCCUPÉ") -> LIBRE | AB27: =IF(ISBLANK(Tableau!$AY27), "LIBRE", "OCCUPÉ") -> LIBRE
A28: =Tableau!A28 -> 203 | B28: =VLOOKUP($A28,LocalisationRemorque,2,0) -> Huy | C28: =VLOOKUP($A28,LocalisationRemorque,3,0) -> Wanze | D28: =CONCATENATE(VLOOKUP($A28,LocalisationRemorque,6,0)," ► ",VLOOKUP($A28,LocalisationRemorque,5,0)) -> Éghezée ► E42 | E28: =IF(ISBLANK(Tableau!$E$28), "LIBRE", "OCCUPÉ") -> OCCUPÉ | F28: =IF(ISBLANK(Tableau!$G$28), "LIBRE", "OCCUPÉ") -> LIBRE | G28: =IF(ISBLANK(Tableau!$I$28), "LIBRE", "OCCUPÉ") -> OCCUPÉ | H28: =IF(ISBLANK(Tableau!$K$28), "LIBRE", "OCCUPÉ") -> LIBRE | I28: =IF(ISBLANK(Tableau!$M$28), "LIBRE", "OCCUPÉ") -> OCCUPÉ | J28: =IF(ISBLANK(Tableau!$O$28), "LIBRE", "OCCUPÉ") -> LIBRE | K28: =IF(ISBLANK(Tableau!$Q$28), "LIBRE", "OCCUPÉ") -> OCCUPÉ | L28: =IF(ISBLANK(Tableau!$S$28), "LIBRE", "OCCUPÉ") -> LIBRE | M28: =IF(ISBLANK(Tableau!$U$28), "LIBRE", "OCCUPÉ") -> OCCUPÉ | N28: =IF(ISBLANK(Tableau!$W$28), "LIBRE", "OCCUPÉ") -> LIBRE | O28: =IF(ISBLANK(Tableau!$Y$28), "LIBRE", "OCCUPÉ") -> LIBRE | P28: =IF(ISBLANK(Tableau!$AA$28), "LIBRE", "OCCUPÉ") -> LIBRE | Q28: =IF(ISBLANK(Tableau!$AC$28), "LIBRE", "OCCUPÉ") -> LIBRE | R28: =IF(ISBLANK(Tableau!$AE$28), "LIBRE", "OCCUPÉ") -> LIBRE | S28: =IF(ISBLANK(Tableau!$AG$28), "LIBRE", "OCCUPÉ") -> LIBRE | T28: =IF(ISBLANK(Tableau!$AI$28), "LIBRE", "OCCUPÉ") -> LIBRE | U28: =IF(ISBLANK(Tableau!$AK$28), "LIBRE", "OCCUPÉ") -> LIBRE | V28: =IF(ISBLANK(Tableau!$AM$28), "LIBRE", "OCCUPÉ") -> LIBRE | W28: =IF(ISBLANK(Tableau!$AO$28), "LIBRE", "OCCUPÉ") -> LIBRE | X28: =IF(ISBLANK(Tableau!$AQ$28), "LIBRE", "OCCUPÉ") -> LIBRE | Y28: =IF(ISBLANK(Tableau!$AS$28), "LIBRE", "OCCUPÉ") -> LIBRE | Z28: =IF(ISBLANK(Tableau!$AU$28), "LIBRE", "OCCUPÉ") -> LIBRE | AA28: =IF(ISBLANK(Tableau!$AW$28), "LIBRE", "OCCUPÉ") -> LIBRE | AB28: =IF(ISBLANK(Tableau!$AY28), "LIBRE", "OCCUPÉ") -> LIBRE | AC28: Plopsa
A29: =Tableau!A29 -> 204 | B29: =VLOOKUP($A29,LocalisationRemorque,2,0) -> Huy | C29: =VLOOKUP($A29,LocalisationRemorque,3,0) -> Vinalmont | D29: =CONCATENATE(VLOOKUP($A29,LocalisationRemorque,6,0)," ► ",VLOOKUP($A29,LocalisationRemorque,5,0)) -> Huy ► E42 | E29: =IF(ISBLANK(Tableau!$E$29), "LIBRE", "OCCUPÉ") -> OCCUPÉ | F29: =IF(ISBLANK(Tableau!$G$29), "LIBRE", "OCCUPÉ") -> LIBRE | G29: =IF(ISBLANK(Tableau!$I$29), "LIBRE", "OCCUPÉ") -> OCCUPÉ | H29: =IF(ISBLANK(Tableau!$K$29), "LIBRE", "OCCUPÉ") -> LIBRE | I29: =IF(ISBLANK(Tableau!$M$29), "LIBRE", "OCCUPÉ") -> OCCUPÉ | J29: =IF(ISBLANK(Tableau!$O$29), "LIBRE", "OCCUPÉ") -> LIBRE | K29: =IF(ISBLANK(Tableau!$Q$29), "LIBRE", "OCCUPÉ") -> OCCUPÉ | L29: =IF(ISBLANK(Tableau!$S$29), "LIBRE", "OCCUPÉ") -> LIBRE | M29: =IF(ISBLANK(Tableau!$U$29), "LIBRE", "OCCUPÉ") -> OCCUPÉ | N29: =IF(ISBLANK(Tableau!$W$29), "LIBRE", "OCCUPÉ") -> LIBRE | O29: =IF(ISBLANK(Tableau!$Y$29), "LIBRE", "OCCUPÉ") -> LIBRE | P29: =IF(ISBLANK(Tableau!$AA$29), "LIBRE", "OCCUPÉ") -> LIBRE | Q29: =IF(ISBLANK(Tableau!$AC$29), "LIBRE", "OCCUPÉ") -> LIBRE | R29: =IF(ISBLANK(Tableau!$AE$29), "LIBRE", "OCCUPÉ") -> LIBRE | S29: =IF(ISBLANK(Tableau!$AG$29), "LIBRE", "OCCUPÉ") -> LIBRE | T29: =IF(ISBLANK(Tableau!$AI$29), "LIBRE", "OCCUPÉ") -> LIBRE | U29: =IF(ISBLANK(Tableau!$AK$29), "LIBRE", "OCCUPÉ") -> LIBRE | V29: =IF(ISBLANK(Tableau!$AM$29), "LIBRE", "OCCUPÉ") -> LIBRE | W29: =IF(ISBLANK(Tableau!$AO$29), "LIBRE", "OCCUPÉ") -> LIBRE | X29: =IF(ISBLANK(Tableau!$AQ$29), "LIBRE", "OCCUPÉ") -> LIBRE | Y29: =IF(ISBLANK(Tableau!$AS$29), "LIBRE", "OCCUPÉ") -> LIBRE | Z29: =IF(ISBLANK(Tableau!$AU$29), "LIBRE", "OCCUPÉ") -> LIBRE | AA29: =IF(ISBLANK(Tableau!$AW$29), "LIBRE", "OCCUPÉ") -> LIBRE | AB29: =IF(ISBLANK(Tableau!$AY29), "LIBRE", "OCCUPÉ") -> LIBRE | AC29: Plopsa
A30: =Tableau!A30 -> 205 | B30: =VLOOKUP($A30,LocalisationRemorque,2,0) -> Huy | C30: =VLOOKUP($A30,LocalisationRemorque,3,0) -> Villers-Le-Bouillet | D30: =CONCATENATE(VLOOKUP($A30,LocalisationRemorque,6,0)," ► ",VLOOKUP($A30,LocalisationRemorque,5,0)) -> Huy ► E42 | E30: =IF(ISBLANK(Tableau!$E$30), "LIBRE", "OCCUPÉ") -> OCCUPÉ | F30: =IF(ISBLANK(Tableau!$G$30), "LIBRE", "OCCUPÉ") -> LIBRE | G30: =IF(ISBLANK(Tableau!$I$30), "LIBRE", "OCCUPÉ") -> OCCUPÉ | H30: =IF(ISBLANK(Tableau!$K$30), "LIBRE", "OCCUPÉ") -> LIBRE | I30: =IF(ISBLANK(Tableau!$M$30), "LIBRE", "OCCUPÉ") -> OCCUPÉ | J30: =IF(ISBLANK(Tableau!$O$30), "LIBRE", "OCCUPÉ") -> LIBRE | K30: =IF(ISBLANK(Tableau!$Q$30), "LIBRE", "OCCUPÉ") -> OCCUPÉ | L30: =IF(ISBLANK(Tableau!$S$30), "LIBRE", "OCCUPÉ") -> LIBRE | M30: =IF(ISBLANK(Tableau!$U$30), "LIBRE", "OCCUPÉ") -> OCCUPÉ | N30: =IF(ISBLANK(Tableau!$W$30), "LIBRE", "OCCUPÉ") -> LIBRE | O30: =IF(ISBLANK(Tableau!$Y$30), "LIBRE", "OCCUPÉ") -> LIBRE | P30: =IF(ISBLANK(Tableau!$AA$30), "LIBRE", "OCCUPÉ") -> LIBRE | Q30: =IF(ISBLANK(Tableau!$AC$30), "LIBRE", "OCCUPÉ") -> LIBRE | R30: =IF(ISBLANK(Tableau!$AE$30), "LIBRE", "OCCUPÉ") -> LIBRE | S30: =IF(ISBLANK(Tableau!$AG$30), "LIBRE", "OCCUPÉ") -> LIBRE | T30: =IF(ISBLANK(Tableau!$AI$30), "LIBRE", "OCCUPÉ") -> LIBRE | U30: =IF(ISBLANK(Tableau!$AK$30), "LIBRE", "OCCUPÉ") -> LIBRE | V30: =IF(ISBLANK(Tableau!$AM$30), "LIBRE", "OCCUPÉ") -> LIBRE | W30: =IF(ISBLANK(Tableau!$AO$30), "LIBRE", "OCCUPÉ") -> LIBRE | X30: =IF(ISBLANK(Tableau!$AQ$30), "LIBRE", "OCCUPÉ") -> LIBRE | Y30: =IF(ISBLANK(Tableau!$AS$30), "LIBRE", "OCCUPÉ") -> LIBRE | Z30: =IF(ISBLANK(Tableau!$AU$30), "LIBRE", "OCCUPÉ") -> LIBRE | AA30: =IF(ISBLANK(Tableau!$AW$30), "LIBRE", "OCCUPÉ") -> LIBRE | AB30: =IF(ISBLANK(Tableau!$AY30), "LIBRE", "OCCUPÉ") -> LIBRE | AC30: Plopsa
A31: =Tableau!A31 -> 206 | B31: =VLOOKUP($A31,LocalisationRemorque,2,0) -> Huy | C31: =VLOOKUP($A31,LocalisationRemorque,3,0) -> Ombret | D31: =CONCATENATE(VLOOKUP($A31,LocalisationRemorque,6,0)," ► ",VLOOKUP($A31,LocalisationRemorque,5,0)) -> Seraing ► Huy | E31: =IF(ISBLANK(Tableau!$E$31), "LIBRE", "OCCUPÉ") -> OCCUPÉ | F31: =IF(ISBLANK(Tableau!$G$31), "LIBRE", "OCCUPÉ") -> LIBRE | G31: =IF(ISBLANK(Tableau!$I$31), "LIBRE", "OCCUPÉ") -> OCCUPÉ | H31: =IF(ISBLANK(Tableau!$K$31), "LIBRE", "OCCUPÉ") -> LIBRE | I31: =IF(ISBLANK(Tableau!$M$31), "LIBRE", "OCCUPÉ") -> OCCUPÉ | J31: =IF(ISBLANK(Tableau!$O$31), "LIBRE", "OCCUPÉ") -> LIBRE | K31: =IF(ISBLANK(Tableau!$Q$31), "LIBRE", "OCCUPÉ") -> OCCUPÉ | L31: =IF(ISBLANK(Tableau!$S$31), "LIBRE", "OCCUPÉ") -> LIBRE | M31: =IF(ISBLANK(Tableau!$U$31), "LIBRE", "OCCUPÉ") -> OCCUPÉ | N31: =IF(ISBLANK(Tableau!$W$31), "LIBRE", "OCCUPÉ") -> LIBRE | O31: =IF(ISBLANK(Tableau!$Y$31), "LIBRE", "OCCUPÉ") -> LIBRE | P31: =IF(ISBLANK(Tableau!$AA$31), "LIBRE", "OCCUPÉ") -> LIBRE | Q31: =IF(ISBLANK(Tableau!$AC$31), "LIBRE", "OCCUPÉ") -> LIBRE | R31: =IF(ISBLANK(Tableau!$AE$31), "LIBRE", "OCCUPÉ") -> LIBRE | S31: =IF(ISBLANK(Tableau!$AG$31), "LIBRE", "OCCUPÉ") -> LIBRE | T31: =IF(ISBLANK(Tableau!$AI$31), "LIBRE", "OCCUPÉ") -> LIBRE | U31: =IF(ISBLANK(Tableau!$AK$31), "LIBRE", "OCCUPÉ") -> LIBRE | V31: =IF(ISBLANK(Tableau!$AM$31), "LIBRE", "OCCUPÉ") -> LIBRE | W31: =IF(ISBLANK(Tableau!$AO$31), "LIBRE", "OCCUPÉ") -> LIBRE | X31: =IF(ISBLANK(Tableau!$AQ$31), "LIBRE", "OCCUPÉ") -> LIBRE | Y31: =IF(ISBLANK(Tableau!$AS$31), "LIBRE", "OCCUPÉ") -> LIBRE | Z31: =IF(ISBLANK(Tableau!$AU$31), "LIBRE", "OCCUPÉ") -> LIBRE | AA31: =IF(ISBLANK(Tableau!$AW$31), "LIBRE", "OCCUPÉ") -> LIBRE | AB31: =IF(ISBLANK(Tableau!$AY31), "LIBRE", "OCCUPÉ") -> LIBRE | AC31: Plopsa
A32: =Tableau!A32 -> 207 | B32: =VLOOKUP($A32,LocalisationRemorque,2,0) -> Huy | C32: =VLOOKUP($A32,LocalisationRemorque,3,0) -> Solière | D32: =CONCATENATE(VLOOKUP($A32,LocalisationRemorque,6,0)," ► ",VLOOKUP($A32,LocalisationRemorque,5,0)) -> Ohey ► Huy | E32: =IF(ISBLANK(Tableau!$E$32), "LIBRE", "OCCUPÉ") -> OCCUPÉ | F32: =IF(ISBLANK(Tableau!$G$32), "LIBRE", "OCCUPÉ") -> LIBRE | G32: =IF(ISBLANK(Tableau!$I$32), "LIBRE", "OCCUPÉ") -> OCCUPÉ | H32: =IF(ISBLANK(Tableau!$K$32), "LIBRE", "OCCUPÉ") -> LIBRE | I32: =IF(ISBLANK(Tableau!$M$32), "LIBRE", "OCCUPÉ") -> OCCUPÉ | J32: =IF(ISBLANK(Tableau!$O$32), "LIBRE", "OCCUPÉ") -> LIBRE | K32: =IF(ISBLANK(Tableau!$Q$32), "LIBRE", "OCCUPÉ") -> OCCUPÉ | L32: =IF(ISBLANK(Tableau!$S$32), "LIBRE", "OCCUPÉ") -> LIBRE | M32: =IF(ISBLANK(Tableau!$U$32), "LIBRE", "OCCUPÉ") -> OCCUPÉ | N32: =IF(ISBLANK(Tableau!$W$32), "LIBRE", "OCCUPÉ") -> LIBRE | O32: =IF(ISBLANK(Tableau!$Y$32), "LIBRE", "OCCUPÉ") -> LIBRE | P32: =IF(ISBLANK(Tableau!$AA$32), "LIBRE", "OCCUPÉ") -> LIBRE | Q32: =IF(ISBLANK(Tableau!$AC$32), "LIBRE", "OCCUPÉ") -> LIBRE | R32: =IF(ISBLANK(Tableau!$AE$32), "LIBRE", "OCCUPÉ") -> LIBRE | S32: =IF(ISBLANK(Tableau!$AG$32), "LIBRE", "OCCUPÉ") -> LIBRE | T32: =IF(ISBLANK(Tableau!$AI$32), "LIBRE", "OCCUPÉ") -> LIBRE | U32: =IF(ISBLANK(Tableau!$AK$32), "LIBRE", "OCCUPÉ") -> LIBRE | V32: =IF(ISBLANK(Tableau!$AM$32), "LIBRE", "OCCUPÉ") -> LIBRE | W32: =IF(ISBLANK(Tableau!$AO$32), "LIBRE", "OCCUPÉ") -> LIBRE | X32: =IF(ISBLANK(Tableau!$AQ$32), "LIBRE", "OCCUPÉ") -> LIBRE | Y32: =IF(ISBLANK(Tableau!$AS$32), "LIBRE", "OCCUPÉ") -> LIBRE | Z32: =IF(ISBLANK(Tableau!$AU$32), "LIBRE", "OCCUPÉ") -> LIBRE | AA32: =IF(ISBLANK(Tableau!$AW$32), "LIBRE", "OCCUPÉ") -> LIBRE | AB32: =IF(ISBLANK(Tableau!$AY32), "LIBRE", "OCCUPÉ") -> LIBRE | AC32: Plopsa
A33: =Tableau!A33 -> 208 | B33: =VLOOKUP($A33,LocalisationRemorque,2,0) -> Huy | C33: =VLOOKUP($A33,LocalisationRemorque,3,0) -> Tihange | D33: =CONCATENATE(VLOOKUP($A33,LocalisationRemorque,6,0)," ► ",VLOOKUP($A33,LocalisationRemorque,5,0)) -> Hamoir ► Huy | E33: =IF(ISBLANK(Tableau!$E$33), "LIBRE", "OCCUPÉ") -> OCCUPÉ | F33: =IF(ISBLANK(Tableau!$G$33), "LIBRE", "OCCUPÉ") -> LIBRE | G33: =IF(ISBLANK(Tableau!$I$33), "LIBRE", "OCCUPÉ") -> OCCUPÉ | H33: =IF(ISBLANK(Tableau!$K$33), "LIBRE", "OCCUPÉ") -> LIBRE | I33: =IF(ISBLANK(Tableau!$M$33), "LIBRE", "OCCUPÉ") -> OCCUPÉ | J33: =IF(ISBLANK(Tableau!$O$33), "LIBRE", "OCCUPÉ") -> LIBRE | K33: =IF(ISBLANK(Tableau!$Q$33), "LIBRE", "OCCUPÉ") -> OCCUPÉ | L33: =IF(ISBLANK(Tableau!$S$33), "LIBRE", "OCCUPÉ") -> LIBRE | M33: =IF(ISBLANK(Tableau!$U$33), "LIBRE", "OCCUPÉ") -> OCCUPÉ | N33: =IF(ISBLANK(Tableau!$W$33), "LIBRE", "OCCUPÉ") -> LIBRE | O33: =IF(ISBLANK(Tableau!$Y$33), "LIBRE", "OCCUPÉ") -> LIBRE | P33: =IF(ISBLANK(Tableau!$AA$33), "LIBRE", "OCCUPÉ") -> LIBRE | Q33: =IF(ISBLANK(Tableau!$AC$33), "LIBRE", "OCCUPÉ") -> LIBRE | R33: =IF(ISBLANK(Tableau!$AE$33), "LIBRE", "OCCUPÉ") -> LIBRE | S33: =IF(ISBLANK(Tableau!$AG$33), "LIBRE", "OCCUPÉ") -> LIBRE | T33: =IF(ISBLANK(Tableau!$AI$33), "LIBRE", "OCCUPÉ") -> LIBRE | U33: =IF(ISBLANK(Tableau!$AK$33), "LIBRE", "OCCUPÉ") -> LIBRE | V33: =IF(ISBLANK(Tableau!$AM$33), "LIBRE", "OCCUPÉ") -> LIBRE | W33: =IF(ISBLANK(Tableau!$AO$33), "LIBRE", "OCCUPÉ") -> LIBRE | X33: =IF(ISBLANK(Tableau!$AQ$33), "LIBRE", "OCCUPÉ") -> LIBRE | Y33: =IF(ISBLANK(Tableau!$AS$33), "LIBRE", "OCCUPÉ") -> LIBRE | Z33: =IF(ISBLANK(Tableau!$AU$33), "LIBRE", "OCCUPÉ") -> LIBRE | AA33: =IF(ISBLANK(Tableau!$AW$33), "LIBRE", "OCCUPÉ") -> LIBRE | AB33: =IF(ISBLANK(Tableau!$AY33), "LIBRE", "OCCUPÉ") -> LIBRE | AC33: Plopsa
A34: =Tableau!A34 -> 209 | B34: =VLOOKUP($A34,LocalisationRemorque,2,0) -> Huy | C34: =VLOOKUP($A34,LocalisationRemorque,3,0) -> Pont de bonne | D34: =CONCATENATE(VLOOKUP($A34,LocalisationRemorque,6,0)," ► ",VLOOKUP($A34,LocalisationRemorque,5,0)) -> Havelange ► Huy | E34: =IF(ISBLANK(Tableau!$E$34), "LIBRE", "OCCUPÉ") -> OCCUPÉ | F34: =IF(ISBLANK(Tableau!$G$34), "LIBRE", "OCCUPÉ") -> LIBRE | G34: =IF(ISBLANK(Tableau!$I$34), "LIBRE", "OCCUPÉ") -> OCCUPÉ | H34: =IF(ISBLANK(Tableau!$K$34), "LIBRE", "OCCUPÉ") -> LIBRE | I34: =IF(ISBLANK(Tableau!$M$34), "LIBRE", "OCCUPÉ") -> OCCUPÉ | J34: =IF(ISBLANK(Tableau!$O$34), "LIBRE", "OCCUPÉ") -> LIBRE | K34: =IF(ISBLANK(Tableau!$Q$34), "LIBRE", "OCCUPÉ") -> OCCUPÉ | L34: =IF(ISBLANK(Tableau!$S$34), "LIBRE", "OCCUPÉ") -> LIBRE | M34: =IF(ISBLANK(Tableau!$U$34), "LIBRE", "OCCUPÉ") -> OCCUPÉ | N34: =IF(ISBLANK(Tableau!$W$34), "LIBRE", "OCCUPÉ") -> LIBRE | O34: =IF(ISBLANK(Tableau!$Y$34), "LIBRE", "OCCUPÉ") -> LIBRE | P34: =IF(ISBLANK(Tableau!$AA$34), "LIBRE", "OCCUPÉ") -> LIBRE | Q34: =IF(ISBLANK(Tableau!$AC$34), "LIBRE", "OCCUPÉ") -> LIBRE | R34: =IF(ISBLANK(Tableau!$AE$34), "LIBRE", "OCCUPÉ") -> LIBRE | S34: =IF(ISBLANK(Tableau!$AG$34), "LIBRE", "OCCUPÉ") -> LIBRE | T34: =IF(ISBLANK(Tableau!$AI$34), "LIBRE", "OCCUPÉ") -> LIBRE | U34: =IF(ISBLANK(Tableau!$AK$34), "LIBRE", "OCCUPÉ") -> LIBRE | V34: =IF(ISBLANK(Tableau!$AM$34), "LIBRE", "OCCUPÉ") -> LIBRE | W34: =IF(ISBLANK(Tableau!$AO$34), "LIBRE", "OCCUPÉ") -> LIBRE | X34: =IF(ISBLANK(Tableau!$AQ$34), "LIBRE", "OCCUPÉ") -> LIBRE | Y34: =IF(ISBLANK(Tableau!$AS$34), "LIBRE", "OCCUPÉ") -> LIBRE | Z34: =IF(ISBLANK(Tableau!$AU$34), "LIBRE", "OCCUPÉ") -> LIBRE | AA34: =IF(ISBLANK(Tableau!$AW$34), "LIBRE", "OCCUPÉ") -> LIBRE | AB34: =IF(ISBLANK(Tableau!$AY34), "LIBRE", "OCCUPÉ") -> LIBRE | AC34: Plopsa
A35: =Tableau!A35 -> 210 | B35: =VLOOKUP($A35,LocalisationRemorque,2,0) -> Huy | C35: =VLOOKUP($A35,LocalisationRemorque,3,0) -> Nandrin | D35: =CONCATENATE(VLOOKUP($A35,LocalisationRemorque,6,0)," ► ",VLOOKUP($A35,LocalisationRemorque,5,0)) -> Marche-en-Famenne ► Liege | E35: =IF(ISBLANK(Tableau!$E$35), "LIBRE", "OCCUPÉ") -> OCCUPÉ | F35: =IF(ISBLANK(Tableau!$G$35), "LIBRE", "OCCUPÉ") -> LIBRE | G35: =IF(ISBLANK(Tableau!$I$35), "LIBRE", "OCCUPÉ") -> OCCUPÉ | H35: =IF(ISBLANK(Tableau!$K$35), "LIBRE", "OCCUPÉ") -> LIBRE | I35: =IF(ISBLANK(Tableau!$M$35), "LIBRE", "OCCUPÉ") -> OCCUPÉ | J35: =IF(ISBLANK(Tableau!$O$35), "LIBRE", "OCCUPÉ") -> LIBRE | K35: =IF(ISBLANK(Tableau!$Q$35), "LIBRE", "OCCUPÉ") -> OCCUPÉ | L35: =IF(ISBLANK(Tableau!$S$35), "LIBRE", "OCCUPÉ") -> LIBRE | M35: =IF(ISBLANK(Tableau!$U$35), "LIBRE", "OCCUPÉ") -> OCCUPÉ | N35: =IF(ISBLANK(Tableau!$W$35), "LIBRE", "OCCUPÉ") -> LIBRE | O35: =IF(ISBLANK(Tableau!$Y$35), "LIBRE", "OCCUPÉ") -> LIBRE | P35: =IF(ISBLANK(Tableau!$AA$35), "LIBRE", "OCCUPÉ") -> LIBRE | Q35: =IF(ISBLANK(Tableau!$AC$35), "LIBRE", "OCCUPÉ") -> OCCUPÉ | R35: =IF(ISBLANK(Tableau!$AE$35), "LIBRE", "OCCUPÉ") -> LIBRE | S35: =IF(ISBLANK(Tableau!$AG$35), "LIBRE", "OCCUPÉ") -> OCCUPÉ | T35: =IF(ISBLANK(Tableau!$AI$35), "LIBRE", "OCCUPÉ") -> LIBRE | U35: =IF(ISBLANK(Tableau!$AK$35), "LIBRE", "OCCUPÉ") -> LIBRE | V35: =IF(ISBLANK(Tableau!$AM$35), "LIBRE", "OCCUPÉ") -> LIBRE | W35: =IF(ISBLANK(Tableau!$AO$35), "LIBRE", "OCCUPÉ") -> OCCUPÉ | X35: =IF(ISBLANK(Tableau!$AQ$35), "LIBRE", "OCCUPÉ") -> LIBRE | Y35: =IF(ISBLANK(Tableau!$AS$35), "LIBRE", "OCCUPÉ") -> LIBRE | Z35: =IF(ISBLANK(Tableau!$AU$35), "LIBRE", "OCCUPÉ") -> LIBRE | AA35: =IF(ISBLANK(Tableau!$AW$35), "LIBRE", "OCCUPÉ") -> LIBRE | AB35: =IF(ISBLANK(Tableau!$AY35), "LIBRE", "OCCUPÉ") -> LIBRE | AC35: Plopsa
A36: =Tableau!A36 -> 211 | B36: =VLOOKUP($A36,LocalisationRemorque,2,0) -> Huy | C36: =VLOOKUP($A36,LocalisationRemorque,3,0) -> Soheit-Tinlot | D36: =CONCATENATE(VLOOKUP($A36,LocalisationRemorque,6,0)," ► ",VLOOKUP($A36,LocalisationRemorque,5,0)) -> Marche-en-Famenne ► Liege | E36: =IF(ISBLANK(Tableau!$E$36), "LIBRE", "OCCUPÉ") -> OCCUPÉ | F36: =IF(ISBLANK(Tableau!$G$36), "LIBRE", "OCCUPÉ") -> LIBRE | G36: =IF(ISBLANK(Tableau!$I$36), "LIBRE", "OCCUPÉ") -> OCCUPÉ | H36: =IF(ISBLANK(Tableau!$K$36), "LIBRE", "OCCUPÉ") -> LIBRE | I36: =IF(ISBLANK(Tableau!$M$36), "LIBRE", "OCCUPÉ") -> OCCUPÉ | J36: =IF(ISBLANK(Tableau!$O$52), "LIBRE", "OCCUPÉ") -> LIBRE | K36: =IF(ISBLANK(Tableau!$Q$36), "LIBRE", "OCCUPÉ") -> OCCUPÉ | L36: =IF(ISBLANK(Tableau!$S$36), "LIBRE", "OCCUPÉ") -> LIBRE | M36: =IF(ISBLANK(Tableau!$U$36), "LIBRE", "OCCUPÉ") -> OCCUPÉ | N36: =IF(ISBLANK(Tableau!$W$36), "LIBRE", "OCCUPÉ") -> LIBRE | O36: =IF(ISBLANK(Tableau!$Y$36), "LIBRE", "OCCUPÉ") -> LIBRE | P36: =IF(ISBLANK(Tableau!$AA$36), "LIBRE", "OCCUPÉ") -> LIBRE | Q36: =IF(ISBLANK(Tableau!$AC$36), "LIBRE", "OCCUPÉ") -> LIBRE | R36: =IF(ISBLANK(Tableau!$AE$36), "LIBRE", "OCCUPÉ") -> LIBRE | S36: =IF(ISBLANK(Tableau!$AG$36), "LIBRE", "OCCUPÉ") -> LIBRE | T36: =IF(ISBLANK(Tableau!$AI$36), "LIBRE", "OCCUPÉ") -> LIBRE | U36: =IF(ISBLANK(Tableau!$AK$36), "LIBRE", "OCCUPÉ") -> LIBRE | V36: =IF(ISBLANK(Tableau!$AM$36), "LIBRE", "OCCUPÉ") -> LIBRE | W36: =IF(ISBLANK(Tableau!$AO$36), "LIBRE", "OCCUPÉ") -> LIBRE | X36: =IF(ISBLANK(Tableau!$AQ$36), "LIBRE", "OCCUPÉ") -> LIBRE | Y36: =IF(ISBLANK(Tableau!$AS$36), "LIBRE", "OCCUPÉ") -> LIBRE | Z36: =IF(ISBLANK(Tableau!$AU$36), "LIBRE", "OCCUPÉ") -> LIBRE | AA36: =IF(ISBLANK(Tableau!$AW$36), "LIBRE", "OCCUPÉ") -> LIBRE | AB36: =IF(ISBLANK(Tableau!$AY36), "LIBRE", "OCCUPÉ") -> LIBRE | AC36: Plopsa
A37: =Tableau!A37 -> 212 | B37: =VLOOKUP($A37,LocalisationRemorque,2,0) -> Flemalle | C37: =VLOOKUP($A37,LocalisationRemorque,3,0) -> Pont dYvoz-Ramet | D37: =CONCATENATE(VLOOKUP($A37,LocalisationRemorque,6,0)," ► ",VLOOKUP($A37,LocalisationRemorque,5,0)) -> Liège ► Huy | E37: =IF(ISBLANK(Tableau!$E$37), "LIBRE", "OCCUPÉ") -> LIBRE | F37: =IF(ISBLANK(Tableau!$G$37), "LIBRE", "OCCUPÉ") -> LIBRE | G37: =IF(ISBLANK(Tableau!$I$37), "LIBRE", "OCCUPÉ") -> LIBRE | H37: =IF(ISBLANK(Tableau!$K$37), "LIBRE", "OCCUPÉ") -> LIBRE | I37: =IF(ISBLANK(Tableau!$M$37), "LIBRE", "OCCUPÉ") -> LIBRE | J37: =IF(ISBLANK(Tableau!$O$37), "LIBRE", "OCCUPÉ") -> LIBRE | K37: =IF(ISBLANK(Tableau!$Q$37), "LIBRE", "OCCUPÉ") -> LIBRE | L37: =IF(ISBLANK(Tableau!$S$37), "LIBRE", "OCCUPÉ") -> LIBRE | M37: =IF(ISBLANK(Tableau!$U$37), "LIBRE", "OCCUPÉ") -> LIBRE | N37: =IF(ISBLANK(Tableau!$W$37), "LIBRE", "OCCUPÉ") -> LIBRE | O37: =IF(ISBLANK(Tableau!$Y$37), "LIBRE", "OCCUPÉ") -> LIBRE | P37: =IF(ISBLANK(Tableau!$AA$37), "LIBRE", "OCCUPÉ") -> LIBRE | Q37: =IF(ISBLANK(Tableau!$AC$37), "LIBRE", "OCCUPÉ") -> LIBRE | R37: =IF(ISBLANK(Tableau!$AE$37), "LIBRE", "OCCUPÉ") -> LIBRE | S37: =IF(ISBLANK(Tableau!$AG$37), "LIBRE", "OCCUPÉ") -> LIBRE | T37: =IF(ISBLANK(Tableau!$AI$37), "LIBRE", "OCCUPÉ") -> LIBRE | U37: =IF(ISBLANK(Tableau!$AK$37), "LIBRE", "OCCUPÉ") -> LIBRE | V37: =IF(ISBLANK(Tableau!$AM$37), "LIBRE", "OCCUPÉ") -> LIBRE | W37: =IF(ISBLANK(Tableau!$AO$37), "LIBRE", "OCCUPÉ") -> LIBRE | X37: =IF(ISBLANK(Tableau!$AQ$37), "LIBRE", "OCCUPÉ") -> LIBRE | Y37: =IF(ISBLANK(Tableau!$AS$37), "LIBRE", "OCCUPÉ") -> LIBRE | Z37: =IF(ISBLANK(Tableau!$AU$37), "LIBRE", "OCCUPÉ") -> LIBRE | AA37: =IF(ISBLANK(Tableau!$AW$37), "LIBRE", "OCCUPÉ") -> LIBRE | AB37: =IF(ISBLANK(Tableau!$AY37), "LIBRE", "OCCUPÉ") -> LIBRE
